#VRML_SIM R2025a utf8

EXTERNPROTO "https://raw.githubusercontent.com/cyberbotics/webots/R2025a/projects/objects/backgrounds/protos/TexturedBackground.proto"
EXTERNPROTO "https://raw.githubusercontent.com/cyberbotics/webots/R2025a/projects/objects/backgrounds/protos/TexturedBackgroundLight.proto"
EXTERNPROTO "https://raw.githubusercontent.com/cyberbotics/webots/R2025a/projects/objects/floors/protos/Floor.proto"

WorldInfo {
  basicTimeStep 2
  contactProperties [
    ContactProperties {
      maxContactJoints 100
    }
  ]
}
Viewpoint {
  orientation -0.4139637593698281 0.2068001389703907 0.8864917982983408 2.307797242392317
  position -0.29268780813579043 -0.2536117795793768 0.8151349342232589
}
TexturedBackground {
}
TexturedBackgroundLight {
}
Floor {
}
Robot {
  translation -0.8100504725434029 0.09916266991634 0.1649630092175172
  rotation 0.0019676000987135147 -0.0027518995359996318 -0.9999942777830259 0.6908889936865332
  children [
    InertialUnit {
      name "imu"
    }
    Shape {
      appearance DEF base_link_material PBRAppearance {
        baseColor 0 0 0
        roughness 1
        metalness 0
      }
      geometry DEF base_link Mesh {
        url [
          "C:/Users/bj/iCloudDrive/Desktop/windows file/research/spider/webots/meshes/base_link.STL"
        ]
      }
      castShadows FALSE
    }
    DEF leg1_left HingeJoint {
      jointParameters HingeJointParameters {
        position -3.761101814655003e-08
        axis 0 0 1
        anchor 0.057411 -0.004797 0
      }
      device [
        RotationalMotor {
          name "leg1_left_coxa"
          maxVelocity 100
          minPosition -3.14
          maxPosition 3.14
          maxTorque 100
        }
        PositionSensor {
          name "leg1_left_coxa_sensor"
        }
      ]
      endPoint Solid {
        translation 0.05809396138490712 -0.005048300626897059 8.104258307584744e-05
        rotation -1.068431126674947e-08 7.572560160108705e-08 -0.999999999999997 0.4234780645580698
        children [
          Shape {
            appearance DEF leg1_left_leg_base_link_material PBRAppearance {
              roughness 1
              metalness 0
            }
            geometry DEF left_leg_base_link Mesh {
              url [
                "C:/Users/bj/iCloudDrive/Desktop/windows file/research/spider/webots/meshes/left_leg_base_link.STL"
              ]
            }
            castShadows FALSE
          }
          HingeJoint {
            jointParameters HingeJointParameters {
              position 0.31999973627675227
              axis -0.336567 0.941659 -4e-06
              anchor 0.02198 0.027937 -0.00929
            }
            device [
              RotationalMotor {
                name "leg1_left_femur"
                maxVelocity 100
                minPosition -3.14
                maxPosition 3.14
                maxTorque 100
              }
              PositionSensor {
                name "leg1_left_femur_sensor"
              }
            ]
            endPoint Solid {
              translation 0.021980016244922795 0.027937007608151924 -0.009289157415159642
              rotation -0.9712663517415641 -0.16176346376846343 0.1745687708734329 1.6022372461422243
              children [
                Shape {
                  appearance DEF leg1_left_leg_link1_material PBRAppearance {
                    baseColor 0 0 0
                    roughness 1
                    metalness 0
                  }
                  geometry DEF left_leg_link1 Mesh {
                    url [
                      "C:/Users/bj/iCloudDrive/Desktop/windows file/research/spider/webots/meshes/left_leg_link1.STL"
                    ]
                  }
                }
                HingeJoint {
                  jointParameters HingeJointParameters {
                    position 0.030000014792701722
                    axis 0 0 1
                    anchor 0.061 0 0
                  }
                  device [
                    RotationalMotor {
                      name "leg1_left_tibia"
                      maxVelocity 100
                      minPosition -3.14
                      maxPosition 3.14
                      maxTorque 100
                    }
                    PositionSensor {
                      name "leg1_left_tibia_sensor"
                    }
                  ]
                  endPoint Solid {
                    translation 0.060997465209919215 4.765212430928021e-05 -2.6667206765029745e-07
                    rotation 1.975372889835256e-06 -1.937179824052487e-06 0.9999999999961725 1.5781001088622348
                    children [
                      Shape {
                        appearance DEF leg1_left_leg_link2_material PBRAppearance {
                          baseColor 0 0 0
                          roughness 1
                          metalness 0
                        }
                        geometry DEF left_leg_link2 Mesh {
                          url [
                            "C:/Users/bj/iCloudDrive/Desktop/windows file/research/spider/webots/meshes/left_leg_link2.STL"
                          ]
                        }
                      }
                    ]
                    name "leg1_left_leg_link2"
                    boundingObject Pose {
                      translation 0.074 0 -0.019
                      rotation 0 1 0 1.5708
                      children [
                        Capsule {
                          height 0.14232
                          radius 0.01
                          subdivision 16
                        }
                      ]
                    }
                    physics Physics {
                      density -1
                      mass 0.1
                      centerOfMass [
                        0.089594 0 -0.018644
                      ]
                      inertiaMatrix [
                        0.000142 0.000142 0.000142
                        0 0 0
                      ]
                    }
                    linearVelocity -4.801420059952633e-09 -1.3282737520050965e-09 -4.909127228955344e-09
                    angularVelocity 3.237158463040029e-08 1.508838393697442e-08 -3.040705420065809e-07
                  }
                }
                HingeJoint {
                  jointParameters HingeJointParameters {
                    position -5.415743109590532e-07
                    axis 0 0 -1
                    anchor 0.0255 0 0
                  }
                  device [
                    RotationalMotor {
                      name "leg1_left_leg_joint3"
                      minPosition -3.14
                      maxPosition 3.14
                      maxTorque 100
                    }
                    PositionSensor {
                      name "leg1_left_leg_joint3_sensor"
                    }
                  ]
                  endPoint Solid {
                    translation 0.025499974196387293 5.534546261941826e-08 -4.41548393959044e-08
                    rotation 7.757984750770193e-09 3.0283130586329594e-09 -0.9999999999999999 0.2117194574215997
                    children [
                      Shape {
                        appearance DEF leg1_left_leg_link3_material PBRAppearance {
                          roughness 1
                          metalness 0
                        }
                        geometry DEF left_leg_link3 Mesh {
                          url [
                            "C:/Users/bj/iCloudDrive/Desktop/windows file/research/spider/webots/meshes/left_leg_link3.STL"
                          ]
                        }
                      }
                      HingeJoint {
                        jointParameters HingeJointParameters {
                          position -6.041959251378115e-07
                          axis -0.008081 -0.00445 -0.999957
                          anchor 0.008493 -0.020001 0
                        }
                        device [
                          RotationalMotor {
                            name "leg1_left_leg_joint4"
                            minPosition -3.14
                            maxPosition 3.14
                            maxTorque 100
                          }
                          PositionSensor {
                            name "leg1_left_leg_joint4_sensor"
                          }
                        ]
                        endPoint Solid {
                          translation 0.008492995877386533 -0.020000994554251028 -4.938798706886567e-09
                          rotation -0.004611990858546099 0.017937988484461837 0.9998284643424852 0.503403617142463
                          children [
                            Shape {
                              appearance DEF leg1_left_leg_link4_material PBRAppearance {
                                roughness 1
                                metalness 0
                              }
                              geometry DEF left_leg_link4 Mesh {
                                url [
                                  "C:/Users/bj/iCloudDrive/Desktop/windows file/research/spider/webots/meshes/left_leg_link4.STL"
                                ]
                              }
                            }
                          ]
                          name "leg1_left_leg_link4"
                          boundingObject USE left_leg_link4
                          physics Physics {
                            density -1
                            mass 0.000537
                            centerOfMass [
                              0.016434 0 -0.019911
                            ]
                            inertiaMatrix [
                              1.8438e-09 4.7249e-09 5.3635e-09
                              4.6176e-20 -8.7449e-13 -1.8552e-20
                            ]
                          }
                          linearVelocity -6.871086026813214e-09 -2.2928895229820195e-10 -4.4784141963595816e-09
                          angularVelocity 3.185910712737863e-08 1.5347140639233203e-08 -3.0416233793157605e-07
                        }
                      }
                    ]
                    name "leg1_left_leg_link3"
                    boundingObject USE left_leg_link3
                    physics Physics {
                      density -1
                      mass 0.004264
                      centerOfMass [
                        0.000431 -0.015395 -0.01826
                      ]
                      inertiaMatrix [
                        1.5353e-06 1.3235e-06 3.5073e-07
                        8.5323e-09 8.9451e-10 -7.4296e-08
                      ]
                    }
                    linearVelocity -1.7284405176491303e-09 4.3348178640806765e-09 -3.7094694466152678e-09
                    angularVelocity 3.185909552685498e-08 1.534711025776888e-08 -3.041623235162796e-07
                  }
                }
              ]
              name "leg1_left_leg_link1"
              boundingObject USE left_leg_link1
              physics Physics {
                density -1
                mass 0.07171
                centerOfMass [
                  0.025933 0.003053 -0.022581
                ]
                inertiaMatrix [
                  5.19971e-05 9.90141e-05 5.4006e-05
                  -3.20773e-06 4.50866e-05 -2.72931e-06
                ]
              }
              linearVelocity -3.586844056843888e-09 5.165993013194802e-09 -3.862538616008773e-09
              angularVelocity 3.2503845523646016e-08 1.6010603871786492e-08 -3.041604920761448e-07
            }
          }
        ]
        name "leg1_left_leg_base_link"
        boundingObject USE left_leg_base_link
        physics Physics {
          density -1
          mass 0.05169
          centerOfMass [
            0.022492 0.007129 -0.014892
          ]
          inertiaMatrix [
            4.24864e-05 4.41958e-05 4.49559e-05
            -1.98151e-05 -1.89033e-05 1.87489e-05
          ]
        }
        linearVelocity -2.4179198542765583e-09 1.2878949967678468e-08 -2.7615626515621324e-09
        angularVelocity 3.2637966974274276e-08 1.693837006656253e-08 -3.044664831854272e-07
      }
    }
    DEF leg2_left HingeJoint {
      jointParameters HingeJointParameters {
        position -1.4243023864117198e-08
        axis 0 0 1
        anchor 0.03286 0.047321 0
      }
      device [
        RotationalMotor {
          name "leg2_left_coxa"
          maxVelocity 100
          minPosition -3.14
          maxPosition 3.14
          maxTorque 100
        }
        PositionSensor {
          name "leg2_left_coxa_sensor"
        }
      ]
      endPoint Solid {
        translation 0.0330600278771249 0.04739955070168432 5.572494516323221e-05
        rotation -8.705505811415706e-08 1.1312824415144372e-07 0.9999999999999898 0.6237199866546501
        children [
          Shape {
            appearance DEF leg2_left_leg_base_link_material PBRAppearance {
              roughness 1
              metalness 0
            }
            geometry USE left_leg_base_link
            castShadows FALSE
          }
          HingeJoint {
            jointParameters HingeJointParameters {
              position 0.3200000775031855
              axis -0.336567 0.941659 -4e-06
              anchor 0.02198 0.027937 -0.00929
            }
            device [
              RotationalMotor {
                name "leg2_left_femur"
                maxVelocity 100
                minPosition -3.14
                maxPosition 3.14
                maxTorque 100
              }
              PositionSensor {
                name "leg2_left_femur_sensor"
              }
            ]
            endPoint Solid {
              translation 0.021979988709103036 0.02793699572464592 -0.009290566526109392
              rotation -0.9712663506890473 -0.16176329534708758 0.17456893279627908 1.6022372806195444
              children [
                Shape {
                  appearance DEF leg2_left_leg_link1_material PBRAppearance {
                    baseColor 0 0 0
                    roughness 1
                    metalness 0
                  }
                  geometry USE left_leg_link1
                }
                HingeJoint {
                  jointParameters HingeJointParameters {
                    position 0.029999998400150815
                    axis 0 0 1
                    anchor 0.061 0 0
                  }
                  device [
                    PositionSensor {
                      name "leg2_left_tibia_sensor"
                    }
                    RotationalMotor {
                      name "leg2_left_tibia"
                      maxVelocity 100
                      minPosition -3.14
                      maxPosition 3.14
                      maxTorque 100
                    }
                  ]
                  endPoint Solid {
                    translation 0.061000640938406944 -1.6710629409821403e-05 2.387560565919586e-08
                    rotation -1.5923305593801275e-07 1.4843285407180702e-07 0.9999999999999764 1.5780999751631675
                    children [
                      Shape {
                        appearance DEF leg2_left_leg_link2_material PBRAppearance {
                          baseColor 0 0 0
                          roughness 1
                          metalness 0
                        }
                        geometry USE left_leg_link2
                      }
                    ]
                    name "leg2_left_leg_link2"
                    boundingObject Pose {
                      translation 0.074 0 -0.019
                      rotation 0 1 0 1.5708
                      children [
                        Capsule {
                          height 0.14232
                          radius 0.01
                          subdivision 16
                        }
                      ]
                    }
                    physics Physics {
                      density -1
                      mass 0.1
                      centerOfMass [
                        0.089594 0 -0.018644
                      ]
                      inertiaMatrix [
                        0.000142 0.000142 0.000142
                        0 0 0
                      ]
                    }
                    linearVelocity -6.898846956100713e-09 1.6550099450028666e-08 -1.1658134724257252e-09
                    angularVelocity 3.231818603140632e-08 1.7830859832464646e-08 -7.251939117009667e-08
                  }
                }
                HingeJoint {
                  jointParameters HingeJointParameters {
                    position 1.089654165491324e-08
                    axis 0 0 -1
                    anchor 0.0255 0 0
                  }
                  device [
                    PositionSensor {
                      name "leg2_left_leg_link3_sensor"
                    }
                    RotationalMotor {
                      name "leg2_left_leg_link3"
                    }
                  ]
                  endPoint Solid {
                    translation 0.025486057433382746 -5.9294264471021104e-05 -7.080417502303135e-11
                    rotation 5.895513938328653e-09 1.103723204345272e-08 0.9999999999999998 6.071465295531353
                    children [
                      Shape {
                        appearance DEF leg2_left_leg_link3_material PBRAppearance {
                          roughness 1
                          metalness 0
                        }
                        geometry USE left_leg_link3
                      }
                      HingeJoint {
                        jointParameters HingeJointParameters {
                          position -2.106620286566132
                          axis -0.008081 -0.00445 -0.999957
                          anchor 0.008493 -0.020001 0
                        }
                        device [
                          RotationalMotor {
                            name "leg2_left_leg_joint4"
                            maxVelocity 0
                            maxTorque 10000
                          }
                          PositionSensor {
                            name "leg2_left_leg_joint4_sensor"
                          }
                        ]
                        endPoint Solid {
                          translation 0.008466324548816196 -0.019970547605473885 4.34638326311808e-07
                          rotation 0.003434662952876299 0.0033253755430675195 0.999988572418654 2.609946329673307
                          children [
                            Shape {
                              appearance DEF leg2_left_leg_link4_material PBRAppearance {
                                roughness 1
                                metalness 0
                              }
                              geometry USE left_leg_link4
                            }
                          ]
                          name "leg2_left_leg_link4"
                          boundingObject USE left_leg_link4
                          physics Physics {
                            density -1
                            mass 0.000537
                            centerOfMass [
                              0.016434 0 -0.019911
                            ]
                            inertiaMatrix [
                              1.8438e-09 4.7249e-09 5.3635e-09
                              4.6176e-20 -8.7449e-13 -1.8552e-20
                            ]
                          }
                          linearVelocity -6.01864495596365e-09 1.6222480229149447e-08 -8.6673261483818e-10
                          angularVelocity 3.248936190063909e-08 1.7209350182029383e-08 -7.251768626794518e-08
                        }
                      }
                    ]
                    name "leg2_left_leg_link3"
                    boundingObject USE left_leg_link3
                    physics Physics {
                      density -1
                      mass 0.004264
                      centerOfMass [
                        0.000431 -0.015395 -0.01826
                      ]
                      inertiaMatrix [
                        1.5353e-06 1.3235e-06 3.5073e-07
                        8.5323e-09 8.9451e-10 -7.4296e-08
                      ]
                    }
                    locked TRUE
                    linearVelocity -5.7219660565545476e-09 1.5715983758575733e-08 -8.476488058210185e-10
                    angularVelocity 3.231904673163712e-08 1.7831197066654746e-08 -7.251947488494502e-08
                  }
                }
              ]
              name "leg2_left_leg_link1"
              boundingObject USE left_leg_link1
              physics Physics {
                density -1
                mass 0.07171
                centerOfMass [
                  0.025933 0.003053 -0.022581
                ]
                inertiaMatrix [
                  5.19971e-05 9.90141e-05 5.4006e-05
                  -3.20773e-06 4.50866e-05 -2.72931e-06
                ]
              }
              linearVelocity -6.2891629631558295e-09 1.6008452404908525e-08 -1.0285843947134946e-09
              angularVelocity 3.2319027212902345e-08 1.7831195964937292e-08 -7.25194854631805e-08
            }
          }
        ]
        name "leg2_left_leg_base_link"
        boundingObject USE left_leg_base_link
        physics Physics {
          density -1
          mass 0.05169
          centerOfMass [
            0.022492 0.007129 -0.014892
          ]
          inertiaMatrix [
            4.24864e-05 4.41958e-05 4.49559e-05
            -3.5018e-07 3.0523e-07 -8.2952e-07
          ]
        }
        linearVelocity -6.779888820169488e-09 1.8414997037518337e-08 -6.578220438651099e-10
        angularVelocity 3.2319911033106014e-08 1.7831598250674545e-08 -7.25188307214751e-08
      }
    }
    DEF leg3_left HingeJoint {
      jointParameters HingeJointParameters {
        position -3.641455908848799e-08
        axis 0 0 1
        anchor -0.024551 0.052118 0
      }
      device [
        RotationalMotor {
          name "leg3_left_coxa"
          maxVelocity 100
          minPosition -3.14
          maxPosition 3.14
          maxTorque 100
        }
        PositionSensor {
          name "leg3_left_coxa_sensor"
        }
      ]
      endPoint Solid {
        translation -0.025035006722791697 0.052447574475502086 1.9022394367296213e-05
        rotation -3.3487273926760083e-09 -1.1303428961180726e-08 0.9999999999999998 1.6708999697940867
        children [
          Shape {
            appearance DEF leg3_left_leg_base_link_material PBRAppearance {
              roughness 1
              metalness 0
            }
            geometry USE left_leg_base_link
            castShadows FALSE
          }
          HingeJoint {
            jointParameters HingeJointParameters {
              position 0.3199997510448899
              axis -0.336567 0.941659 -4e-06
              anchor 0.02198 0.027937 -0.00929
            }
            device [
              RotationalMotor {
                name "leg3_left_femur"
                maxVelocity 100
                minPosition -3.14
                maxPosition 3.14
                maxTorque 100
              }
              PositionSensor {
                name "leg3_left_femur_sensor"
              }
            ]
            endPoint Solid {
              translation 0.021979722152342687 0.027936899779571582 -0.009290894050097259
              rotation -0.9712663518468356 -0.161763455810649 0.17456877766180093 1.6022372161682839
              children [
                Shape {
                  appearance DEF leg3_left_leg_link1_material PBRAppearance {
                    baseColor 0 0 0
                    roughness 1
                    metalness 0
                  }
                  geometry USE left_leg_link1
                }
                HingeJoint {
                  jointParameters HingeJointParameters {
                    position 0.030000013247344335
                    axis 0 0 1
                    anchor 0.061 0 0
                  }
                  device [
                    PositionSensor {
                      name "leg3_left_tibia_sensor"
                    }
                    RotationalMotor {
                      name "leg3_left_tibia"
                      maxVelocity 100
                      minPosition -3.14
                      maxPosition 3.14
                      maxTorque 100
                    }
                  ]
                  endPoint Solid {
                    translation 0.06100082312673226 -2.1355718425140844e-05 -7.152269207444354e-09
                    rotation -2.0673377741724207e-07 1.9283522295471643e-07 0.9999999999999599 1.5780999898399082
                    children [
                      Shape {
                        appearance DEF leg3_left_leg_link2_material PBRAppearance {
                          baseColor 0 0 0
                          roughness 1
                          metalness 0
                        }
                        geometry USE left_leg_link2
                      }
                    ]
                    name "leg3_left_leg_link2"
                    boundingObject Pose {
                      translation 0.074 0 -0.019
                      rotation 0 1 0 1.5708
                      children [
                        Capsule {
                          height 0.14232
                          radius 0.01
                          subdivision 16
                        }
                      ]
                    }
                    physics Physics {
                      density -1
                      mass 0.1
                      centerOfMass [
                        0.089594 0 -0.018644
                      ]
                      inertiaMatrix [
                        0.000142 0.000142 0.000142
                        0 0 0
                      ]
                    }
                    linearVelocity 4.657417183973358e-09 1.3964173669444801e-09 3.821044431005025e-09
                    angularVelocity 3.1144386992597036e-08 1.9590161441118765e-08 -3.0693057998306696e-07
                  }
                }
                HingeJoint {
                  jointParameters HingeJointParameters {
                    position 8.706441765273383e-09
                    axis 0 0 -1
                    anchor 0.0255 0 0
                  }
                  device [
                    PositionSensor {
                      name "leg3_left_leg_link3_sensor"
                    }
                    RotationalMotor {
                      name "leg3_left_leg_link3"
                    }
                  ]
                  endPoint Solid {
                    translation 0.025487453457609874 -6.930209104077162e-05 4.4143664723605933e-08
                    rotation 2.1746411365051133e-08 3.0872027054795394e-08 0.9999999999999993 6.07146529726864
                    children [
                      Shape {
                        appearance DEF leg3_left_leg_link3_material PBRAppearance {
                          roughness 1
                          metalness 0
                        }
                        geometry USE left_leg_link3
                      }
                      HingeJoint {
                        jointParameters HingeJointParameters {
                          position 9.750505404989607e-10
                          axis -0.008081 -0.00445 -0.999957
                          anchor 0.008493 -0.020001 0
                        }
                        device [
                          RotationalMotor {
                            name "leg3_left_leg_joint4"
                            maxTorque 100
                          }
                          PositionSensor {
                            name "leg3_left_leg_joint4_sensor"
                          }
                        ]
                        endPoint Solid {
                          translation 0.008496984641519304 -0.020000444598952883 4.940304816332597e-09
                          rotation -0.004612002398107551 0.017938008227161458 0.9998284639350503 0.5034029986810199
                          children [
                            Shape {
                              appearance DEF leg3_left_leg_link4_material PBRAppearance {
                                roughness 1
                                metalness 0
                              }
                              geometry USE left_leg_link4
                            }
                          ]
                          name "leg3_left_leg_link4"
                          boundingObject USE left_leg_link4
                          physics Physics {
                            density -1
                            mass 0.000537
                            centerOfMass [
                              0.016434 0 -0.019911
                            ]
                            inertiaMatrix [
                              1.8438e-09 4.7249e-09 5.3635e-09
                              4.6176e-20 -8.7449e-13 -1.8552e-20
                            ]
                          }
                          linearVelocity 5.987559357353653e-09 2.693748293171603e-09 3.494262610611527e-09
                          angularVelocity 3.255726230225959e-08 1.884708269342575e-08 -3.068323524157441e-07
                        }
                      }
                    ]
                    name "leg3_left_leg_link3"
                    boundingObject USE left_leg_link3
                    physics Physics {
                      density -1
                      mass 0.004264
                      centerOfMass [
                        0.000431 -0.015395 -0.01826
                      ]
                      inertiaMatrix [
                        1.5353e-06 1.3235e-06 3.5073e-07
                        8.5323e-09 8.9451e-10 -7.4296e-08
                      ]
                    }
                    linearVelocity -5.93780099303205e-10 4.961248415953818e-09 2.935223218978147e-09
                    angularVelocity 3.255726227035325e-08 1.8847074864916027e-08 -3.06832313750869e-07
                  }
                }
              ]
              name "leg3_left_leg_link1"
              boundingObject USE left_leg_link1
              physics Physics {
                density -1
                mass 0.0053
                centerOfMass [
                  0.025933 0.003053 -0.022581
                ]
                inertiaMatrix [
                  5.19971e-05 9.90141e-05 5.4006e-05
                  -3.20773e-06 4.50866e-05 -2.72931e-06
                ]
              }
              linearVelocity -3.627738499161607e-10 4.029517084790665e-09 2.902450588571291e-09
              angularVelocity 3.1657917492045087e-08 1.907432638632452e-08 -3.0683419029664037e-07
            }
          }
        ]
        name "leg3_left_leg_base_link"
        boundingObject USE left_leg_base_link
        physics Physics {
          density -1
          mass 0.05169
          centerOfMass [
            0.022492 0.007129 -0.014892
          ]
          inertiaMatrix [
            4.24864e-05 4.41958e-05 4.49559e-05
            -1.98151e-05 -1.89033e-05 1.87489e-05
          ]
        }
        linearVelocity -6.348956079768485e-09 1.1324165133876835e-08 2.1788817821215147e-09
        angularVelocity 3.218258299074798e-08 1.8553875864553505e-08 -3.068849557299949e-07
      }
    }
    DEF leg3_right HingeJoint {
      jointParameters HingeJointParameters {
        position 1.3711060115716015e-08
        axis 0 0 1
        anchor -0.057411 0.004797 0
      }
      device [
        RotationalMotor {
          name "leg3_right_coxa"
          maxVelocity 100
          minPosition -3.14
          maxPosition 3.14
          maxTorque 100
        }
        PositionSensor {
          name "leg3_right_coxa_sensor"
        }
      ]
      endPoint Solid {
        translation -0.05741128791615172 0.004796581224744448 -1.3015074797340047e-06
        rotation -3.5393539518685265e-08 1.2764599993864842e-09 0.9999999999999992 2.678100003419067
        children [
          Shape {
            appearance DEF leg4_right_leg_base_link_material PBRAppearance {
              roughness 1
              metalness 0
            }
            geometry DEF right_leg_base_link Mesh {
              url [
                "C:/Users/bj/iCloudDrive/Desktop/windows file/research/spider/webots/meshes/right_leg_base_link.STL"
              ]
            }
            castShadows FALSE
          }
          HingeJoint {
            jointParameters HingeJointParameters {
              position -0.5200000801557213
              axis 0.38825 -0.921554 -3e-06
              anchor 0.035081 -0.00574 -0.00929
            }
            device [
              RotationalMotor {
                name "leg3_right_femur"
                maxVelocity 100
                minPosition -3.14
                maxPosition 3.14
                maxTorque 100
              }
              PositionSensor {
                name "leg3_right_femur_sensor"
              }
            ]
            endPoint Solid {
              translation 0.035081040329697354 -0.005739655851330186 -0.009290455253121362
              rotation 0.9614845424748018 0.19624067788758331 0.19245017777139842 1.6092706669799937
              children [
                Shape {
                  appearance DEF leg4_right_leg_link1_material PBRAppearance {
                    baseColor 0 0 0
                    roughness 1
                    metalness 0
                  }
                  geometry DEF right_leg_link1 Mesh {
                    url [
                      "C:/Users/bj/iCloudDrive/Desktop/windows file/research/spider/webots/meshes/right_leg_link1.STL"
                    ]
                  }
                }
                HingeJoint {
                  jointParameters HingeJointParameters {
                    position 0.2199999991400824
                    axis 0 0 1
                    anchor 0.061 0 0
                  }
                  device [
                    RotationalMotor {
                      name "leg3_right_tibia"
                      maxVelocity 100
                      minPosition -3.14
                      maxPosition 3.14
                      maxTorque 100
                    }
                    PositionSensor {
                      name "leg3_right_tibia_sensor"
                    }
                  ]
                  endPoint Solid {
                    translation 0.06100015542008616 -3.333354847360313e-06 -4.7165228195256095e-08
                    rotation -2.7834149718375357e-08 -3.025362938483046e-08 -0.9999999999999992 1.5573000007120161
                    children [
                      Shape {
                        appearance DEF leg4_right_leg_link2_material PBRAppearance {
                          baseColor 0 0 0
                          roughness 1
                          metalness 0
                        }
                        geometry DEF right_leg_link2 Mesh {
                          url [
                            "C:/Users/bj/iCloudDrive/Desktop/windows file/research/spider/webots/meshes/right_leg_link2.STL"
                          ]
                        }
                      }
                    ]
                    name "leg4_right_leg_link2"
                    boundingObject Pose {
                      translation 0.074 0 -0.019
                      rotation 0 1 0 1.5708
                      children [
                        Capsule {
                          height 0.14232
                          radius 0.01
                          subdivision 16
                        }
                      ]
                    }
                    physics Physics {
                      density -1
                      mass 0.1
                      centerOfMass [
                        0.089594 0 -0.018644
                      ]
                      inertiaMatrix [
                        0.000142 0.000142 0.000142
                        0 0 0
                      ]
                    }
                    linearVelocity -2.4581044493600725e-08 1.2759022642062912e-09 5.249486658698288e-09
                    angularVelocity 3.2513711550536184e-08 1.8541829313253884e-08 2.2366147168063208e-07
                  }
                }
                HingeJoint {
                  jointParameters HingeJointParameters {
                    position -0.02999937169991325
                    axis 0 0 -1
                    anchor 0.025507 0 0
                  }
                  device [
                    RotationalMotor {
                      name "leg4_right_leg_joint3"
                      minPosition -3.14
                      maxPosition 3.14
                      maxTorque 100
                    }
                    PositionSensor {
                      name "leg4_right_leg_joint3_sensor"
                    }
                  ]
                  endPoint Solid {
                    translation 0.025506998768935574 -8.07934979257209e-08 -1.4894566829903837e-10
                    rotation -1.3548594519683736e-08 1.0100712874853742e-09 1 0.11819637310451096
                    children [
                      Shape {
                        appearance DEF leg4_right_leg_link3_material PBRAppearance {
                          roughness 1
                          metalness 0
                        }
                        geometry DEF right_leg_link3 Mesh {
                          url [
                            "C:/Users/bj/iCloudDrive/Desktop/windows file/research/spider/webots/meshes/right_leg_link3.STL"
                          ]
                        }
                      }
                      HingeJoint {
                        jointParameters HingeJointParameters {
                          position 2.3717045112803127e-07
                          axis 0 0 -1.000003
                          anchor 0.0085 0.019 -0.01074
                        }
                        device [
                          RotationalMotor {
                            name "leg4_right_leg_joint4"
                            minPosition -3.14
                            maxPosition 3.14
                            maxTorque 100
                          }
                          PositionSensor {
                            name "leg4_right_leg_joint4_sensor"
                          }
                        ]
                        endPoint Solid {
                          translation 0.008499998878665068 0.018999991646187032 -0.010740000015535545
                          rotation -0.004610998481353756 -0.024886973957594784 -0.9996796372939877 0.3665452449486873
                          children [
                            Shape {
                              appearance DEF leg4_right_leg_link4_material PBRAppearance {
                                roughness 1
                                metalness 0
                              }
                              geometry DEF right_leg_link4 Mesh {
                                url [
                                  "C:/Users/bj/iCloudDrive/Desktop/windows file/research/spider/webots/meshes/right_leg_link4.STL"
                                ]
                              }
                            }
                          ]
                          name "leg4_right_leg_link4"
                          boundingObject USE right_leg_link4
                          physics Physics {
                            density -1
                            mass 0.000537
                            centerOfMass [
                              0.015829 0.000934 -0.006825
                            ]
                            inertiaMatrix [
                              1.8438e-09 4.7249e-09 5.3635e-09
                              -4.6086e-19 8.7449e-13 -3.9428e-20
                            ]
                          }
                          linearVelocity -2.0596680019081005e-08 3.102019372023761e-10 4.776544086289517e-09
                          angularVelocity 3.19527305379887e-08 1.7947456266662636e-08 2.2365987326237523e-07
                        }
                      }
                    ]
                    name "leg4_right_leg_link3"
                    boundingObject USE right_leg_link3
                    physics Physics {
                      density -1
                      mass 0.004611
                      centerOfMass [
                        0.000404 0.014672 -0.020116
                      ]
                      inertiaMatrix [
                        1.552e-06 1.3255e-06 3.6852e-07
                        -8.5323e-09 8.9451e-10 7.5364e-08
                      ]
                    }
                    linearVelocity -1.664238934887295e-08 3.7379466098214e-09 3.936568040624737e-09
                    angularVelocity 3.1952699472188524e-08 1.794748801293973e-08 2.2365986574786047e-07
                  }
                }
              ]
              name "leg4_right_leg_link1"
              boundingObject USE right_leg_link1
              physics Physics {
                density -1
                mass 0.07171
                centerOfMass [
                  0.025933 -0.003053 -0.022581
                ]
                inertiaMatrix [
                  5.19971e-05 9.90141e-05 5.4006e-05
                  -3.20773e-06 4.50866e-05 -2.72931e-06
                ]
              }
              linearVelocity -1.6818990093295835e-08 3.658525352244559e-09 3.9681140661558195e-09
              angularVelocity 3.1667369265078647e-08 1.7644627789842878e-08 2.2365903483116794e-07
            }
          }
        ]
        name "leg4_right_leg_base_link"
        boundingObject USE right_leg_base_link
        physics Physics {
          density -1
          mass 0.05169
          centerOfMass [
            0.021397 0.009944 -0.014892
          ]
          inertiaMatrix [
            4.24864e-05 4.41958e-05 4.49559e-05
            -1.98151e-05 -1.89033e-05 1.87489e-05
          ]
        }
        linearVelocity -1.2363654506303061e-08 9.451792711561488e-09 2.8822296283274157e-09
        angularVelocity 3.1667539231258925e-08 1.764598369824129e-08 2.236595951896079e-07
      }
    }
    DEF leg2_right HingeJoint {
      jointParameters HingeJointParameters {
        position 3.910819024863219e-08
        axis 0 0 1
        anchor -0.03286 -0.047321 0
      }
      device [
        RotationalMotor {
          name "leg2_right_coxa"
          maxVelocity 100
          minPosition -3.14
          maxPosition 3.14
          maxTorque 100
        }
        PositionSensor {
          name "leg2_right_coxa_sensor"
        }
      ]
      endPoint Solid {
        translation -0.03286145413792722 -0.04732176388068664 7.709800100286161e-07
        rotation -1.5758925208037873e-07 -4.2816815256523666e-08 -0.9999999999999866 2.5578997104518226
        children [
          Shape {
            appearance DEF leg5_right_leg_base_link_material PBRAppearance {
              roughness 1
              metalness 0
            }
            geometry USE right_leg_base_link
            castShadows FALSE
          }
          HingeJoint {
            jointParameters HingeJointParameters {
              position -0.5199997225188594
              axis 0.38825 -0.921554 -3e-06
              anchor 0.035081 -0.00574 -0.00929
            }
            device [
              RotationalMotor {
                name "leg2_right_femur"
                maxVelocity 100
                minPosition -3.14
                maxPosition 3.14
                maxTorque 100
              }
              PositionSensor {
                name "leg2_right_femur_sensor"
              }
            ]
            endPoint Solid {
              translation 0.03508131704368333 -0.005739871861107057 -0.009290458676175624
              rotation 0.961484548230999 0.196240494228766 0.192450336289344 1.6092707217361688
              children [
                Shape {
                  appearance DEF leg5_right_leg_link1_material PBRAppearance {
                    baseColor 0 0 0
                    roughness 1
                    metalness 0
                  }
                  geometry USE right_leg_link1
                }
                HingeJoint {
                  jointParameters HingeJointParameters {
                    position 0.2199999919639232
                    axis 0 0 1
                    anchor 0.061 0 0
                  }
                  device [
                    RotationalMotor {
                      name "leg2_right_tibia"
                      maxVelocity 100
                      minPosition -3.14
                      maxPosition 3.14
                      maxTorque 100
                    }
                    PositionSensor {
                      name "leg2_right_tibia_sensor"
                    }
                  ]
                  endPoint Solid {
                    translation 0.06100006837124222 4.880173911683555e-06 4.770633767747757e-07
                    rotation 2.5377472498059007e-08 2.3185465733872437e-08 -0.9999999999999994 1.5573000259084901
                    children [
                      Shape {
                        appearance DEF leg5_right_leg_link2_material PBRAppearance {
                          baseColor 0 0 0
                          roughness 1
                          metalness 0
                        }
                        geometry USE right_leg_link2
                      }
                    ]
                    name "leg5_right_leg_link2"
                    boundingObject Pose {
                      translation 0.074 0 -0.019
                      rotation 0 1 0 1.5708
                      children [
                        Capsule {
                          height 0.14232
                          radius 0.01
                          subdivision 16
                        }
                      ]
                    }
                    physics Physics {
                      density -1
                      mass 0.1
                      centerOfMass [
                        0.089594 0 -0.018644
                      ]
                      inertiaMatrix [
                        0.000142 0.000142 0.000142
                        0 0 0
                      ]
                    }
                    linearVelocity 6.868885389540276e-10 -7.51857075869977e-09 1.2033562733225562e-09
                    angularVelocity 4.734930261643583e-08 -2.6822349731119353e-08 4.508140031006903e-07
                  }
                }
                HingeJoint {
                  jointParameters HingeJointParameters {
                    position 7.2292938037041544e-09
                    axis 0 0 -1
                    anchor 0.025507 0 0
                  }
                  device [
                    RotationalMotor {
                      name "leg5_right_leg_joint3"
                      minPosition -3.14
                      maxPosition 3.14
                      maxTorque 100
                    }
                    PositionSensor {
                      name "leg5_right_leg_joint3_sensor"
                    }
                  ]
                  endPoint Solid {
                    translation 0.025506998864848494 -8.079504181330828e-08 -1.665112492332808e-11
                    rotation -1.814982839722161e-08 1.056823169069632e-09 0.9999999999999998 0.08819699129482267
                    children [
                      Shape {
                        appearance DEF leg5_right_leg_link3_material PBRAppearance {
                          roughness 1
                          metalness 0
                        }
                        geometry USE right_leg_link3
                      }
                      HingeJoint {
                        jointParameters HingeJointParameters {
                          position -3.916727709772055e-09
                          axis 0 0 -1.000003
                          anchor 0.0085 0.019 -0.01074
                        }
                        device [
                          RotationalMotor {
                            name "leg5_right_leg_joint4"
                            minPosition -3.14
                            maxPosition 3.14
                            maxTorque 100
                          }
                          PositionSensor {
                            name "leg5_right_leg_joint4_sensor"
                          }
                        ]
                        endPoint Solid {
                          translation 0.008499999139694637 0.018999991615267494 -0.01074000000173761
                          rotation -0.004610998479019189 -0.02488699073534424 -0.9996796368763172 0.3665450034132192
                          children [
                            Shape {
                              appearance DEF leg5_right_leg_link4_material PBRAppearance {
                                roughness 1
                                metalness 0
                              }
                              geometry USE right_leg_link4
                            }
                          ]
                          name "leg5_right_leg_link4"
                          boundingObject USE right_leg_link4
                          physics Physics {
                            density -1
                            mass 0.000537
                            centerOfMass [
                              0.015829 0.000934 -0.006825
                            ]
                            inertiaMatrix [
                              1.8438e-09 4.7249e-09 5.3635e-09
                              -4.6086e-19 8.7449e-13 -3.9428e-20
                            ]
                          }
                          linearVelocity -8.762012988706315e-10 -1.1741255205041372e-08 1.2000677905889719e-09
                          angularVelocity 3.2782276557800184e-08 1.85863854688471e-08 4.5084223743052905e-07
                        }
                      }
                    ]
                    name "leg5_right_leg_link3"
                    boundingObject USE right_leg_link3
                    physics Physics {
                      density -1
                      mass 0.004611
                      centerOfMass [
                        0.000404 0.014672 -0.020116
                      ]
                      inertiaMatrix [
                        1.552e-06 1.3255e-06 3.6852e-07
                        -8.5323e-09 8.9451e-10 7.5364e-08
                      ]
                    }
                    linearVelocity -2.7478402230138744e-09 -1.3146372558221946e-09 9.063163904033268e-10
                    angularVelocity 3.2782266166132814e-08 1.8586384352739984e-08 4.5084223289005066e-07
                  }
                }
              ]
              name "leg5_right_leg_link1"
              boundingObject USE right_leg_link1
              physics Physics {
                density -1
                mass 0.07171
                centerOfMass [
                  0.025933 -0.003053 -0.022581
                ]
                inertiaMatrix [
                  5.19971e-05 9.90141e-05 5.4006e-05
                  -3.20773e-06 4.50866e-05 -2.72931e-06
                ]
              }
              linearVelocity -1.855573797521158e-09 -9.350006709394562e-10 8.257746986245332e-10
              angularVelocity 3.283444251361908e-08 1.841238402538377e-08 4.508422478386928e-07
            }
          }
        ]
        name "leg5_right_leg_base_link"
        boundingObject USE right_leg_base_link
        physics Physics {
          density -1
          mass 0.05169
          centerOfMass [
            0.021397 0.009944 -0.014892
          ]
          inertiaMatrix [
            4.24864e-05 4.41958e-05 4.49559e-05
            -1.98151e-05 -1.89033e-05 1.87489e-05
          ]
        }
        linearVelocity -4.4664582394121806e-09 7.580321712735996e-09 6.947218965705346e-10
        angularVelocity 3.202369122626901e-08 1.797332241516587e-08 4.5122686874849355e-07
      }
    }
    DEF leg1_right HingeJoint {
      jointParameters HingeJointParameters {
        position -1.478200244169107e-08
        axis 0 0 1
        anchor 0.024551 -0.052118 0
      }
      device [
        RotationalMotor {
          name "leg1_right_coxa"
          maxVelocity 100
          minPosition -3.14
          maxPosition 3.14
          maxTorque 100
        }
        PositionSensor {
          name "leg1_right_coxa_sensor"
        }
      ]
      endPoint Solid {
        translation 0.024550712083727923 -0.0521184187753145 -1.3015074352418164e-06
        rotation 4.919241773701545e-09 5.111767033626818e-08 -0.9999999999999987 1.510700026940657
        children [
          Shape {
            appearance DEF leg6_right_leg_base_link_material PBRAppearance {
              roughness 1
              metalness 0
            }
            geometry USE right_leg_base_link
            castShadows FALSE
          }
          HingeJoint {
            jointParameters HingeJointParameters {
              position -0.52000008018386
              axis 0.38825 -0.921554 -3e-06
              anchor 0.035081 -0.00574 -0.00929
            }
            device [
              RotationalMotor {
                name "leg1_right_femur"
                maxVelocity 100
                minPosition -3.14
                maxPosition 3.14
                maxTorque 100
              }
              PositionSensor {
                name "leg1_right_femur_sensor"
              }
            ]
            endPoint Solid {
              translation 0.03508126839193224 -0.005740219518690011 -0.009290455079634864
              rotation 0.9614845460812675 0.19624067210996385 0.19245016564484566 1.6092706400920438
              children [
                Shape {
                  appearance DEF leg6_right_leg_link1_material PBRAppearance {
                    baseColor 0 0 0
                    roughness 1
                    metalness 0
                  }
                  geometry USE right_leg_link1
                }
                HingeJoint {
                  jointParameters HingeJointParameters {
                    position 0.21999999912513493
                    axis 0 0 1
                    anchor 0.061 0 0
                  }
                  device [
                    RotationalMotor {
                      name "leg1_right_tibia"
                      maxVelocity 100
                      minPosition -3.14
                      maxPosition 3.14
                      maxTorque 100
                    }
                    PositionSensor {
                      name "leg1_right_tibia_sensor"
                    }
                  ]
                  endPoint Solid {
                    translation 0.06100004492845138 -3.353981378908541e-09 1.1559992740828312e-07
                    rotation -4.791414035868815e-09 -5.704683262320705e-09 -1 1.557299985076428
                    children [
                      Shape {
                        appearance DEF leg6_right_leg_link2_material PBRAppearance {
                          baseColor 0 0 0
                          roughness 1
                          metalness 0
                        }
                        geometry USE right_leg_link2
                      }
                    ]
                    name "leg6_right_leg_link2"
                    boundingObject Pose {
                      translation 0.074 0 -0.019
                      rotation 0 1 0 1.5708
                      children [
                        Capsule {
                          height 0.14232
                          radius 0.01
                          subdivision 16
                        }
                      ]
                    }
                    physics Physics {
                      density -1
                      mass 0.1
                      centerOfMass [
                        0.089594 0 -0.018644
                      ]
                      inertiaMatrix [
                        0.000142 0.000142 0.000142
                        0 0 0
                      ]
                    }
                    linearVelocity -1.0426831000055238e-08 1.943226164931311e-08 -3.970438362532747e-09
                    angularVelocity 3.102899188048439e-08 1.813720289216914e-08 -7.458792531154277e-08
                  }
                }
                HingeJoint {
                  jointParameters HingeJointParameters {
                    position -1.630752277315062e-08
                    axis 0 0 -1
                    anchor 0.025507 0 0
                  }
                  device [
                    RotationalMotor {
                      name "leg6_right_leg_joint3"
                      minPosition -3.14
                      maxPosition 3.14
                      maxTorque 100
                    }
                    PositionSensor {
                      name "leg6_right_leg_joint3_sensor"
                    }
                  ]
                  endPoint Solid {
                    translation 0.025506998798263427 -8.079396822782372e-08 1.3253678710078987e-10
                    rotation -1.8123987375798806e-08 1.0680585418360403e-09 0.9999999999999998 0.08819701761857736
                    children [
                      Shape {
                        appearance DEF leg6_right_leg_link3_material PBRAppearance {
                          roughness 1
                          metalness 0
                        }
                        geometry USE right_leg_link3
                      }
                      HingeJoint {
                        jointParameters HingeJointParameters {
                          position 2.4247391875311376e-09
                          axis 0 0 -1.000003
                          anchor 0.0085 0.019 -0.01074
                        }
                        device [
                          RotationalMotor {
                            name "leg6_right_leg_joint4"
                            minPosition -3.14
                            maxPosition 3.14
                            maxTorque 100
                          }
                          PositionSensor {
                            name "leg6_right_leg_joint4_sensor"
                          }
                        ]
                        endPoint Solid {
                          translation 0.008499999132787057 0.018999991615989895 -0.010739999986175613
                          rotation -0.004610998479110029 -0.024886990308462566 -0.9996796368869438 0.36654500956808095
                          children [
                            Shape {
                              appearance DEF leg6_right_leg_link4_material PBRAppearance {
                                roughness 1
                                metalness 0
                              }
                              geometry USE right_leg_link4
                            }
                          ]
                          name "leg6_right_leg_link4"
                          boundingObject USE right_leg_link4
                          physics Physics {
                            density -1
                            mass 0.000537
                            centerOfMass [
                              0.015829 0.000934 -0.006825
                            ]
                            inertiaMatrix [
                              1.8438e-09 4.7249e-09 5.3635e-09
                              -4.6086e-19 8.7449e-13 -3.9428e-20
                            ]
                          }
                          linearVelocity -7.487418237046378e-09 1.600659853626059e-08 -3.555218939309167e-09
                          angularVelocity 3.213875662567674e-08 1.7875784165353138e-08 -7.458552641574872e-08
                        }
                      }
                    ]
                    name "leg6_right_leg_link3"
                    boundingObject USE right_leg_link3
                    physics Physics {
                      density -1
                      mass 0.004611
                      centerOfMass [
                        0.000404 0.014672 -0.020116
                      ]
                      inertiaMatrix [
                        1.552e-06 1.3255e-06 3.6852e-07
                        -8.5323e-09 8.9451e-10 7.5364e-08
                      ]
                    }
                    linearVelocity -5.8733926599009046e-09 1.5458340171156164e-08 -2.991155890410351e-09
                    angularVelocity 3.213874904927544e-08 1.7875779764259743e-08 -7.458553289736126e-08
                  }
                }
              ]
              name "leg6_right_leg_link1"
              boundingObject USE right_leg_link1
              physics Physics {
                density -1
                mass 0.07171
                centerOfMass [
                  0.025933 -0.003053 -0.022581
                ]
                inertiaMatrix [
                  5.19971e-05 9.90141e-05 5.4006e-05
                  -3.20773e-06 4.50866e-05 -2.72931e-06
                ]
              }
              linearVelocity -6.321841351128751e-09 1.5867904293913653e-08 -3.0866226911201105e-09
              angularVelocity 3.2322920044010534e-08 1.7832272769654934e-08 -7.45851544682317e-08
            }
          }
        ]
        name "leg6_right_leg_base_link"
        boundingObject USE right_leg_base_link
        physics Physics {
          density -1
          mass 0.05169
          centerOfMass [
            0.021397 0.009944 -0.014892
          ]
          inertiaMatrix [
            4.24864e-05 4.41958e-05 4.49559e-05
            -1.98151e-05 -1.89033e-05 1.87489e-05
          ]
        }
        linearVelocity -3.969842930348556e-09 1.5611036555939565e-08 -2.133051543697322e-09
        angularVelocity 3.232403285655335e-08 1.7832813174607698e-08 -7.45855569142364e-08
      }
    }
  ]
  name "Spider"
  boundingObject USE base_link
  physics Physics {
    density -1
    mass 0.42388
    centerOfMass [
      -5.5e-05 9.9e-05 -0.018675
    ]
    inertiaMatrix [
      0.000707768 0.000694017 0.00111424
      1.1258e-07 1.521e-08 -7.61e-09
    ]
  }
  controller "init_controller"
  controllerArgs [
    ""
  ]
  cpuConsumption 1000
  linearVelocity -6.1924081903621295e-09 1.64010012685391e-08 6.497647041009897e-11
  angularVelocity 3.200838907950615e-08 1.774379021426043e-08 6.927454829989206e-08
}
