#VRML_SIM R2025a utf8

EXTERNPROTO "https://raw.githubusercontent.com/cyberbotics/webots/R2025a/projects/objects/backgrounds/protos/TexturedBackground.proto"
EXTERNPROTO "https://raw.githubusercontent.com/cyberbotics/webots/R2025a/projects/objects/backgrounds/protos/TexturedBackgroundLight.proto"
EXTERNPROTO "https://raw.githubusercontent.com/cyberbotics/webots/R2025a/projects/objects/floors/protos/Floor.proto"

WorldInfo {
  basicTimeStep 5
  contactProperties [
    ContactProperties {
      maxContactJoints 49
    }
  ]
}
Viewpoint {
  orientation 0.14064866173706098 -0.957108453602065 -0.2533009316900311 5.231798511487457
  position 2.1319257643089804 0.859778158906757 1.0888773713690376
}
TexturedBackground {
}
TexturedBackgroundLight {
}
Floor {
}
Robot {
  translation 2.8432968158588645 0.7872100246520582 0.10383760990416395
  rotation 0.00011023472508296868 0.0032960140350926973 0.9999945620551072 -2.2305652801380065
  children [
    InertialUnit {
      name "imu"
    }
    Shape {
      appearance DEF base_link_material PBRAppearance {
        baseColor 0 0 0
        roughness 1
        metalness 0
      }
      geometry DEF base_link Mesh {
        url [
          "C:/Users/bj/iCloudDrive/Desktop/windows file/research/spider/webots/meshes/base_link.STL"
        ]
      }
      castShadows FALSE
    }
    DEF leg1_left HingeJoint {
      jointParameters HingeJointParameters {
        position 0.17377711155501796
        axis 0 0 1
        anchor 0.057411 -0.004797 0
      }
      device [
        RotationalMotor {
          name "leg1_left_coxa"
          minPosition -3.14
          maxPosition 3.14
          maxTorque 100
        }
        PositionSensor {
          name "leg1_left_coxa_sensor"
        }
      ]
      endPoint Solid {
        translation 0.05812712594780893 -0.004926429074121204 8.104258307584771e-05
        rotation -2.905408644266437e-08 1.257535474921724e-07 -0.9999999999999916 0.2497009162027711
        children [
          Shape {
            appearance DEF leg1_left_leg_base_link_material PBRAppearance {
              roughness 1
              metalness 0
            }
            geometry DEF left_leg_base_link Mesh {
              url [
                "C:/Users/bj/iCloudDrive/Desktop/windows file/research/spider/webots/meshes/left_leg_base_link.STL"
              ]
            }
            castShadows FALSE
          }
          HingeJoint {
            jointParameters HingeJointParameters {
              position -0.07574729427544581
              axis -0.336567 0.941659 -4e-06
              anchor 0.02198 0.027937 -0.00929
            }
            device [
              RotationalMotor {
                name "leg1_left_femur"
                minPosition -3.14
                maxPosition 3.14
                maxTorque 100
              }
              PositionSensor {
                name "leg1_left_femur_sensor"
              }
            ]
            endPoint Solid {
              translation 0.02197970908069481 0.027936897821514 -0.009289215655363019
              rotation -0.9346882865732618 -0.3549257628704465 -0.019634403315907163 1.571185176258906
              children [
                Shape {
                  appearance DEF leg1_left_leg_link1_material PBRAppearance {
                    baseColor 0 0 0
                    roughness 1
                    metalness 0
                  }
                  geometry DEF left_leg_link1 Mesh {
                    url [
                      "C:/Users/bj/iCloudDrive/Desktop/windows file/research/spider/webots/meshes/left_leg_link1.STL"
                    ]
                  }
                }
                HingeJoint {
                  jointParameters HingeJointParameters {
                    position -0.3158317501106548
                    axis 0 0 1
                    anchor 0.061 0 0
                  }
                  device [
                    RotationalMotor {
                      name "leg1_left_tibia"
                      minPosition -3.14
                      maxPosition 3.14
                      maxTorque 100
                    }
                    PositionSensor {
                      name "leg1_left_tibia_sensor"
                    }
                  ]
                  endPoint Solid {
                    translation 0.060998264112402015 9.528989099243821e-06 -1.6750615006166954e-08
                    rotation 1.4088022479716358e-07 -6.491480495994855e-08 0.9999999999999879 1.2322682253566528
                    children [
                      Shape {
                        appearance DEF leg1_left_leg_link2_material PBRAppearance {
                          baseColor 0 0 0
                          roughness 1
                          metalness 0
                        }
                        geometry DEF left_leg_link2 Mesh {
                          url [
                            "C:/Users/bj/iCloudDrive/Desktop/windows file/research/spider/webots/meshes/left_leg_link2.STL"
                          ]
                        }
                      }
                    ]
                    name "leg1_left_leg_link2"
                    boundingObject USE left_leg_link2
                    physics Physics {
                      density -1
                      mass 0.1
                      centerOfMass [
                        0.089594 0 -0.018644
                      ]
                      inertiaMatrix [
                        0.000142 0.000142 0.000142
                        0 0 0
                      ]
                    }
                    linearVelocity -0.0033297614988868833 -0.013354110948773425 -0.003624404666176423
                    angularVelocity -0.1312637028029998 -0.03640765388254009 0.04825908421419034
                  }
                }
                HingeJoint {
                  jointParameters HingeJointParameters {
                    position -3.536182062081899e-07
                    axis 0 0 -1
                    anchor 0.0255 0 0
                  }
                  device [
                    RotationalMotor {
                      name "leg1_left_leg_joint3"
                      minPosition -3.14
                      maxPosition 3.14
                      maxTorque 100
                    }
                    PositionSensor {
                      name "leg1_left_leg_joint3_sensor"
                    }
                  ]
                  endPoint Solid {
                    translation 0.025499974196397695 5.534546746936373e-08 -4.4154839395904476e-08
                    rotation 7.757978173886967e-09 3.0283096511897977e-09 -1 0.21171964537773805
                    children [
                      Shape {
                        appearance DEF leg1_left_leg_link3_material PBRAppearance {
                          roughness 1
                          metalness 0
                        }
                        geometry DEF left_leg_link3 Mesh {
                          url [
                            "C:/Users/bj/iCloudDrive/Desktop/windows file/research/spider/webots/meshes/left_leg_link3.STL"
                          ]
                        }
                      }
                      HingeJoint {
                        jointParameters HingeJointParameters {
                          position -4.3767278644219193e-07
                          axis -0.008081 -0.00445 -0.999957
                          anchor 0.008493 -0.020001 0
                        }
                        device [
                          RotationalMotor {
                            name "leg1_left_leg_joint4"
                            minPosition -3.14
                            maxPosition 3.14
                            maxTorque 100
                          }
                          PositionSensor {
                            name "leg1_left_leg_joint4_sensor"
                          }
                        ]
                        endPoint Solid {
                          translation 0.008492995877387444 -0.020000994554250348 -4.938798717269764e-09
                          rotation -0.004611993844986358 0.01793799390730249 0.9998284642314177 0.5034034506478915
                          children [
                            Shape {
                              appearance DEF leg1_left_leg_link4_material PBRAppearance {
                                roughness 1
                                metalness 0
                              }
                              geometry DEF left_leg_link4 Mesh {
                                url [
                                  "C:/Users/bj/iCloudDrive/Desktop/windows file/research/spider/webots/meshes/left_leg_link4.STL"
                                ]
                              }
                            }
                          ]
                          name "leg1_left_leg_link4"
                          boundingObject USE left_leg_link4
                          physics Physics {
                            density -1
                            mass 0.000537
                            centerOfMass [
                              0.016434 0 -0.019911
                            ]
                            inertiaMatrix [
                              1.8438e-09 4.7249e-09 5.3635e-09
                              4.6176e-20 -8.7449e-13 -1.8552e-20
                            ]
                          }
                          linearVelocity -0.010970681017267413 -0.003642919161618844 -0.005034772677153333
                          angularVelocity 0.11535059134460643 -0.19318329896730949 0.049599225231675655
                        }
                      }
                    ]
                    name "leg1_left_leg_link3"
                    boundingObject USE left_leg_link3
                    physics Physics {
                      density -1
                      mass 0.004264
                      centerOfMass [
                        0.000431 -0.015395 -0.01826
                      ]
                      inertiaMatrix [
                        1.5353e-06 1.3235e-06 3.5073e-07
                        8.5323e-09 8.9451e-10 -7.4296e-08
                      ]
                    }
                    linearVelocity -0.009861588164481551 -0.0018886009219638744 -0.0007782525603566835
                    angularVelocity 0.11535059128290578 -0.1931832989412314 0.04959922525951196
                  }
                }
              ]
              name "leg1_left_leg_link1"
              boundingObject USE left_leg_link1
              physics Physics {
                density -1
                mass 0.07171
                centerOfMass [
                  0.025933 0.003053 -0.022581
                ]
                inertiaMatrix [
                  5.19971e-05 9.90141e-05 5.4006e-05
                  -3.20773e-06 4.50866e-05 -2.72931e-06
                ]
              }
              linearVelocity -0.006538598354958532 -0.0005231614224301041 -0.003190035802587669
              angularVelocity 0.11535059107286662 -0.19318329879287127 0.04959922532861015
            }
          }
        ]
        name "leg1_left_leg_base_link"
        boundingObject USE left_leg_base_link
        physics Physics {
          density -1
          mass 0.05169
          centerOfMass [
            0.022492 0.007129 -0.014892
          ]
          inertiaMatrix [
            4.24864e-05 4.41958e-05 4.49559e-05
            -1.98151e-05 -1.89033e-05 1.87489e-05
          ]
        }
        linearVelocity -0.00609393501370841 0.0007385454141137089 0.0019092906266533424
        angularVelocity -0.08329958209990554 -0.06689843270254396 0.04851920004722166
      }
    }
    DEF leg2_left HingeJoint {
      jointParameters HingeJointParameters {
        position -6.385958302705184e-08
        axis 0 0 1
        anchor 0.03286 0.047321 0
      }
      device [
        RotationalMotor {
          name "leg2_left_coxa"
          minPosition -3.14
          maxPosition 3.14
          maxTorque 100
        }
        PositionSensor {
          name "leg2_left_coxa_sensor"
        }
      ]
      endPoint Solid {
        translation 0.03306002788101436 0.04739955069177994 5.5724945163232236e-05
        rotation -8.705506199887773e-08 1.1312825499451693e-07 0.9999999999999898 0.6237199371397112
        children [
          Shape {
            appearance DEF leg2_left_leg_base_link_material PBRAppearance {
              roughness 1
              metalness 0
            }
            geometry USE left_leg_base_link
            castShadows FALSE
          }
          HingeJoint {
            jointParameters HingeJointParameters {
              position -0.594591167189482
              axis -0.336567 0.941659 -4e-06
              anchor 0.02198 0.027937 -0.00929
            }
            device [
              RotationalMotor {
                name "leg2_left_femur"
                minPosition -3.14
                maxPosition 3.14
                maxTorque 100
              }
              PositionSensor {
                name "leg2_left_femur_sensor"
              }
            ]
            endPoint Solid {
              translation 0.021980415819663295 0.027937148383055384 -0.00929035520989868
              rotation -0.7833477980947976 -0.5619991485968576 -0.265562015725968 1.6467465723634782
              children [
                Shape {
                  appearance DEF leg2_left_leg_link1_material PBRAppearance {
                    baseColor 0 0 0
                    roughness 1
                    metalness 0
                  }
                  geometry USE left_leg_link1
                }
                HingeJoint {
                  jointParameters HingeJointParameters {
                    position 0.5228813130815098
                    axis 0 0 1
                    anchor 0.061 0 0
                  }
                  device [
                    PositionSensor {
                      name "leg2_left_tibia_sensor"
                    }
                    RotationalMotor {
                      name "leg2_left_tibia"
                      minPosition -3.14
                      maxPosition 3.14
                      maxTorque 100
                    }
                  ]
                  endPoint Solid {
                    translation 0.06100847155472416 -1.4418345878410834e-05 2.3875605659195945e-08
                    rotation -1.5729235145172903e-07 8.672091429001596e-08 0.9999999999999839 2.0709812898445175
                    children [
                      Shape {
                        appearance DEF leg2_left_leg_link2_material PBRAppearance {
                          baseColor 0 0 0
                          roughness 1
                          metalness 0
                        }
                        geometry USE left_leg_link2
                      }
                    ]
                    name "leg2_left_leg_link2"
                    boundingObject USE left_leg_link2
                    physics Physics {
                      density -1
                      mass 0.1
                      centerOfMass [
                        0.089594 0 -0.018644
                      ]
                      inertiaMatrix [
                        0.000142 0.000142 0.000142
                        0 0 0
                      ]
                    }
                    linearVelocity -0.01330783628876089 0.012250150866110322 0.02478252983523468
                    angularVelocity -0.04171027268429549 -0.054150256904922006 -0.028394332521522778
                  }
                }
                HingeJoint {
                  jointParameters HingeJointParameters {
                    position 3.4327771998703086e-09
                    axis 0 0 -1
                    anchor 0.0255 0 0
                  }
                  device [
                    PositionSensor {
                      name "leg2_left_leg_link3_sensor"
                    }
                    RotationalMotor {
                      name "leg2_left_leg_link3"
                    }
                  ]
                  endPoint Solid {
                    translation 0.0254860574338253 -5.9294264575085004e-05 -7.080417502303135e-11
                    rotation 5.8955141041965934e-09 1.103723245309504e-08 0.9999999999999999 6.071465302995106
                    children [
                      Shape {
                        appearance DEF leg2_left_leg_link3_material PBRAppearance {
                          roughness 1
                          metalness 0
                        }
                        geometry USE left_leg_link3
                      }
                      HingeJoint {
                        jointParameters HingeJointParameters {
                          position -1.0980852379064246e-05
                          axis -0.008081 -0.00445 -0.999957
                          anchor 0.008493 -0.020001 0
                        }
                        device [
                          RotationalMotor {
                            name "leg2_left_leg_joint4"
                            maxVelocity 0
                            maxTorque 10000
                          }
                          PositionSensor {
                            name "leg2_left_leg_joint4_sensor"
                          }
                        ]
                        endPoint Solid {
                          translation 0.008532805051155137 -0.01999360575620871 -5.317901359745377e-13
                          rotation -0.0046118055914994 0.017937650843257425 0.9998284712546505 0.5034139764071123
                          children [
                            Shape {
                              appearance DEF leg2_left_leg_link4_material PBRAppearance {
                                roughness 1
                                metalness 0
                              }
                              geometry USE left_leg_link4
                            }
                          ]
                          name "leg2_left_leg_link4"
                          boundingObject USE left_leg_link4
                          physics Physics {
                            density -1
                            mass 0.000537
                            centerOfMass [
                              0.016434 0 -0.019911
                            ]
                            inertiaMatrix [
                              1.8438e-09 4.7249e-09 5.3635e-09
                              4.6176e-20 -8.7449e-13 -1.8552e-20
                            ]
                          }
                          linearVelocity -0.01587675447851581 0.015489421768792911 0.014321498592889578
                          angularVelocity -0.33866225251064336 -0.14838841710298697 -0.02855622027050054
                        }
                      }
                    ]
                    name "leg2_left_leg_link3"
                    boundingObject USE left_leg_link3
                    physics Physics {
                      density -1
                      mass 0.004264
                      centerOfMass [
                        0.000431 -0.015395 -0.01826
                      ]
                      inertiaMatrix [
                        1.5353e-06 1.3235e-06 3.5073e-07
                        8.5323e-09 8.9451e-10 -7.4296e-08
                      ]
                    }
                    locked TRUE
                    linearVelocity -0.012746042733024574 0.009227686113801554 0.0097282049779716
                    angularVelocity -0.3386622532162572 -0.1483884173213157 -0.028556220258934898
                  }
                }
              ]
              name "leg2_left_leg_link1"
              boundingObject USE left_leg_link1
              physics Physics {
                density -1
                mass 0.07171
                centerOfMass [
                  0.025933 0.003053 -0.022581
                ]
                inertiaMatrix [
                  5.19971e-05 9.90141e-05 5.4006e-05
                  -3.20773e-06 4.50866e-05 -2.72931e-06
                ]
              }
              linearVelocity -0.011939039200043848 0.006260024879471804 0.015582867234677751
              angularVelocity -0.33866225299420794 -0.14838841727950328 -0.0285562200703166
            }
          }
        ]
        name "leg2_left_leg_base_link"
        boundingObject USE left_leg_base_link
        physics Physics {
          density -1
          mass 0.05169
          centerOfMass [
            0.022492 0.007129 -0.014892
          ]
          inertiaMatrix [
            4.24864e-05 4.41958e-05 4.49559e-05
            -3.5018e-07 3.0523e-07 -8.2952e-07
          ]
        }
        linearVelocity -0.008109913251322485 -0.00035909759347943016 0.008295258596084374
        angularVelocity -0.08312800295562321 -0.0672926920411304 -0.028417486998230976
      }
    }
    DEF leg3_left HingeJoint {
      jointParameters HingeJointParameters {
        position -0.1737770224547792
        axis 0 0 1
        anchor -0.024551 0.052118 0
      }
      device [
        RotationalMotor {
          name "leg3_left_coxa"
          minPosition -3.14
          maxPosition 3.14
          maxTorque 100
        }
        PositionSensor {
          name "leg3_left_coxa_sensor"
        }
      ]
      endPoint Solid {
        translation -0.024970732333483216 0.05252629720895296 1.902239436729621e-05
        rotation -4.704006101485861e-09 -1.1953640003177242e-08 1 1.4971229830152433
        children [
          Shape {
            appearance DEF leg3_left_leg_base_link_material PBRAppearance {
              roughness 1
              metalness 0
            }
            geometry USE left_leg_base_link
            castShadows FALSE
          }
          HingeJoint {
            jointParameters HingeJointParameters {
              position -0.07574696897138378
              axis -0.336567 0.941659 -4e-06
              anchor 0.02198 0.027937 -0.00929
            }
            device [
              RotationalMotor {
                name "leg3_left_femur"
                minPosition -3.14
                maxPosition 3.14
                maxTorque 100
              }
              PositionSensor {
                name "leg3_left_femur_sensor"
              }
            ]
            endPoint Solid {
              translation 0.021980068196492553 0.02793702346220228 -0.009290938811905982
              rotation -0.9346883452564131 -0.35492561731331085 -0.019634240922261688 1.5711851383267463
              children [
                Shape {
                  appearance DEF leg3_left_leg_link1_material PBRAppearance {
                    baseColor 0 0 0
                    roughness 1
                    metalness 0
                  }
                  geometry USE left_leg_link1
                }
                HingeJoint {
                  jointParameters HingeJointParameters {
                    position -0.3158315179123131
                    axis 0 0 1
                    anchor 0.061 0 0
                  }
                  device [
                    PositionSensor {
                      name "leg3_left_tibia_sensor"
                    }
                    RotationalMotor {
                      name "leg3_left_tibia"
                      minPosition -3.14
                      maxPosition 3.14
                      maxTorque 100
                    }
                  ]
                  endPoint Solid {
                    translation 0.060993535250534595 -2.0370352510960092e-05 -7.152269207444359e-09
                    rotation -2.0935261329480276e-07 2.769662464431187e-07 0.9999999999999398 1.2322684586802668
                    children [
                      Shape {
                        appearance DEF leg3_left_leg_link2_material PBRAppearance {
                          baseColor 0 0 0
                          roughness 1
                          metalness 0
                        }
                        geometry USE left_leg_link2
                      }
                    ]
                    name "leg3_left_leg_link2"
                    boundingObject USE left_leg_link2
                    physics Physics {
                      density -1
                      mass 0.1
                      centerOfMass [
                        0.089594 0 -0.018644
                      ]
                      inertiaMatrix [
                        0.000142 0.000142 0.000142
                        0 0 0
                      ]
                    }
                    linearVelocity -0.0009052302597530018 -0.022376613945059354 0.008878782232578092
                    angularVelocity -0.10457095536241263 -0.12025644329872835 -0.10513494534910382
                  }
                }
                HingeJoint {
                  jointParameters HingeJointParameters {
                    position 2.7036441176241567e-09
                    axis 0 0 -1
                    anchor 0.0255 0 0
                  }
                  device [
                    PositionSensor {
                      name "leg3_left_leg_link3_sensor"
                    }
                    RotationalMotor {
                      name "leg3_left_leg_link3"
                    }
                  ]
                  endPoint Solid {
                    translation 0.02548745345802588 -6.930209111608594e-05 4.4143664723605933e-08
                    rotation 2.174641188665278e-08 3.087202799209302e-08 0.9999999999999992 6.071465303271431
                    children [
                      Shape {
                        appearance DEF leg3_left_leg_link3_material PBRAppearance {
                          roughness 1
                          metalness 0
                        }
                        geometry USE left_leg_link3
                      }
                      HingeJoint {
                        jointParameters HingeJointParameters {
                          position 1.7380300636938835e-09
                          axis -0.008081 -0.00445 -0.999957
                          anchor 0.008493 -0.020001 0
                        }
                        device [
                          RotationalMotor {
                            name "leg3_left_leg_joint4"
                            maxTorque 100
                          }
                          PositionSensor {
                            name "leg3_left_leg_joint4_sensor"
                          }
                        ]
                        endPoint Solid {
                          translation 0.00849698464151944 -0.02000044459895386 4.940304819592103e-09
                          rotation -0.0046120024025215235 0.017938008235176467 0.9998284639348861 0.5034029984349426
                          children [
                            Shape {
                              appearance DEF leg3_left_leg_link4_material PBRAppearance {
                                roughness 1
                                metalness 0
                              }
                              geometry USE left_leg_link4
                            }
                          ]
                          name "leg3_left_leg_link4"
                          boundingObject USE left_leg_link4
                          physics Physics {
                            density -1
                            mass 0.000537
                            centerOfMass [
                              0.016434 0 -0.019911
                            ]
                            inertiaMatrix [
                              1.8438e-09 4.7249e-09 5.3635e-09
                              4.6176e-20 -8.7449e-13 -1.8552e-20
                            ]
                          }
                          linearVelocity -0.004440655677358149 -0.007530192760960432 0.0029479373830365043
                          angularVelocity 0.0065193587146793325 0.15003760086110657 -0.10628099177387346
                        }
                      }
                    ]
                    name "leg3_left_leg_link3"
                    boundingObject USE left_leg_link3
                    physics Physics {
                      density -1
                      mass 0.004264
                      centerOfMass [
                        0.000431 -0.015395 -0.01826
                      ]
                      inertiaMatrix [
                        1.5353e-06 1.3235e-06 3.5073e-07
                        8.5323e-09 8.9451e-10 -7.4296e-08
                      ]
                    }
                    linearVelocity -0.004935167637843517 -0.005547329317979391 0.005717802806575295
                    angularVelocity 0.006519358883086265 0.150037601245578 -0.10628099178266152
                  }
                }
              ]
              name "leg3_left_leg_link1"
              boundingObject USE left_leg_link1
              physics Physics {
                density -1
                mass 0.0053
                centerOfMass [
                  0.025933 0.003053 -0.022581
                ]
                inertiaMatrix [
                  5.19971e-05 9.90141e-05 5.4006e-05
                  -3.20773e-06 4.50866e-05 -2.72931e-06
                ]
              }
              linearVelocity -0.008117202735179511 -0.006242283271691701 0.004541823733472169
              angularVelocity 0.006519358913148701 0.15003760097924954 -0.10628099169196056
            }
          }
        ]
        name "leg3_left_leg_base_link"
        boundingObject USE left_leg_base_link
        physics Physics {
          density -1
          mass 0.05169
          centerOfMass [
            0.022492 0.007129 -0.014892
          ]
          inertiaMatrix [
            4.24864e-05 4.41958e-05 4.49559e-05
            -1.98151e-05 -1.89033e-05 1.87489e-05
          ]
        }
        linearVelocity -0.007245582269982988 -0.003655797150404273 0.007357937020652391
        angularVelocity -0.08296375664084422 -0.06768698982495626 -0.10535644502759865
      }
    }
    DEF leg3_right HingeJoint {
      jointParameters HingeJointParameters {
        position 0.17377803389595323
        axis 0 0 1
        anchor -0.057411 0.004797 0
      }
      device [
        RotationalMotor {
          name "leg3_right_coxa"
          minPosition -3.14
          maxPosition 3.14
          maxTorque 100
        }
        PositionSensor {
          name "leg3_right_coxa_sensor"
        }
      ]
      endPoint Solid {
        translation -0.0574112111715134 0.004796537750049202 -1.3015074797340069e-06
        rotation -3.478958252755767e-08 -1.7702229323314757e-09 0.9999999999999993 2.851878023603961
        children [
          Shape {
            appearance DEF leg4_right_leg_base_link_material PBRAppearance {
              roughness 1
              metalness 0
            }
            geometry DEF right_leg_base_link Mesh {
              url [
                "C:/Users/bj/iCloudDrive/Desktop/windows file/research/spider/webots/meshes/right_leg_base_link.STL"
              ]
            }
            castShadows FALSE
          }
          HingeJoint {
            jointParameters HingeJointParameters {
              position -0.14812010344303703
              axis 0.38825 -0.921554 -3e-06
              anchor 0.035081 -0.00574 -0.00929
            }
            device [
              RotationalMotor {
                name "leg3_right_femur"
                minPosition -3.14
                maxPosition 3.14
                maxTorque 100
              }
              PositionSensor {
                name "leg3_right_femur_sensor"
              }
            ]
            endPoint Solid {
              translation 0.03508118201957565 -0.005739596157795433 -0.009290362078090782
              rotation 0.9365209423597199 0.014420221591959891 0.35031497503090103 1.7111475837889711
              children [
                Shape {
                  appearance DEF leg4_right_leg_link1_material PBRAppearance {
                    baseColor 0 0 0
                    roughness 1
                    metalness 0
                  }
                  geometry DEF right_leg_link1 Mesh {
                    url [
                      "C:/Users/bj/iCloudDrive/Desktop/windows file/research/spider/webots/meshes/right_leg_link1.STL"
                    ]
                  }
                }
                HingeJoint {
                  jointParameters HingeJointParameters {
                    position 0.5843297253650874
                    axis 0 0 1
                    anchor 0.061 0 0
                  }
                  device [
                    RotationalMotor {
                      name "leg3_right_tibia"
                      minPosition -3.14
                      maxPosition 3.14
                      maxTorque 100
                    }
                    PositionSensor {
                      name "leg3_right_tibia_sensor"
                    }
                  ]
                  endPoint Solid {
                    translation 0.06100133297006589 -3.0591830192147464e-06 -4.716522819525601e-08
                    rotation -2.737181175717562e-08 -4.35033922692608e-08 -0.9999999999999987 1.1929702744870128
                    children [
                      Shape {
                        appearance DEF leg4_right_leg_link2_material PBRAppearance {
                          baseColor 0 0 0
                          roughness 1
                          metalness 0
                        }
                        geometry DEF right_leg_link2 Mesh {
                          url [
                            "C:/Users/bj/iCloudDrive/Desktop/windows file/research/spider/webots/meshes/right_leg_link2.STL"
                          ]
                        }
                      }
                    ]
                    name "leg4_right_leg_link2"
                    boundingObject USE right_leg_link2
                    physics Physics {
                      density -1
                      mass 0.1
                      centerOfMass [
                        0.089594 0 -0.018644
                      ]
                      inertiaMatrix [
                        0.000142 0.000142 0.000142
                        0 0 0
                      ]
                    }
                    linearVelocity -0.004351472569831949 0.0058875327366196975 -0.0025382201300984363
                    angularVelocity -0.00038558333729742534 -0.11782456243538714 0.04895521824927642
                  }
                }
                HingeJoint {
                  jointParameters HingeJointParameters {
                    position -0.029999729375723212
                    axis 0 0 -1
                    anchor 0.025507 0 0
                  }
                  device [
                    RotationalMotor {
                      name "leg4_right_leg_joint3"
                      minPosition -3.14
                      maxPosition 3.14
                      maxTorque 100
                    }
                    PositionSensor {
                      name "leg4_right_leg_joint3_sensor"
                    }
                  ]
                  endPoint Solid {
                    translation 0.02550699876896447 -8.079349836592323e-08 -1.4894566829903845e-10
                    rotation -1.3548553748585601e-08 1.010065811467245e-09 0.9999999999999998 0.11819673078036956
                    children [
                      Shape {
                        appearance DEF leg4_right_leg_link3_material PBRAppearance {
                          roughness 1
                          metalness 0
                        }
                        geometry DEF right_leg_link3 Mesh {
                          url [
                            "C:/Users/bj/iCloudDrive/Desktop/windows file/research/spider/webots/meshes/right_leg_link3.STL"
                          ]
                        }
                      }
                      HingeJoint {
                        jointParameters HingeJointParameters {
                          position -5.6707174920619876e-08
                          axis 0 0 -1.000003
                          anchor 0.0085 0.019 -0.01074
                        }
                        device [
                          RotationalMotor {
                            name "leg4_right_leg_joint4"
                            minPosition -3.14
                            maxPosition 3.14
                            maxTorque 100
                          }
                          PositionSensor {
                            name "leg4_right_leg_joint4_sensor"
                          }
                        ]
                        endPoint Solid {
                          translation 0.008499998878667522 0.018999991646186702 -0.010740000015535545
                          rotation -0.004610998478703845 -0.024886994358051997 -0.9996796367861315 0.36654495116521807
                          children [
                            Shape {
                              appearance DEF leg4_right_leg_link4_material PBRAppearance {
                                roughness 1
                                metalness 0
                              }
                              geometry DEF right_leg_link4 Mesh {
                                url [
                                  "C:/Users/bj/iCloudDrive/Desktop/windows file/research/spider/webots/meshes/right_leg_link4.STL"
                                ]
                              }
                            }
                          ]
                          name "leg4_right_leg_link4"
                          boundingObject USE right_leg_link4
                          physics Physics {
                            density -1
                            mass 0.000537
                            centerOfMass [
                              0.015829 0.000934 -0.006825
                            ]
                            inertiaMatrix [
                              1.8438e-09 4.7249e-09 5.3635e-09
                              -4.6086e-19 8.7449e-13 -3.9428e-20
                            ]
                          }
                          linearVelocity -0.009258780169588933 0.005284099125592781 -0.0046629514488394615
                          angularVelocity -0.12173214823535827 -0.04329131372032197 0.04830810956528579
                        }
                      }
                    ]
                    name "leg4_right_leg_link3"
                    boundingObject USE right_leg_link3
                    physics Physics {
                      density -1
                      mass 0.004611
                      centerOfMass [
                        0.000404 0.014672 -0.020116
                      ]
                      inertiaMatrix [
                        1.552e-06 1.3255e-06 3.6852e-07
                        -8.5323e-09 8.9451e-10 7.5364e-08
                      ]
                    }
                    linearVelocity -0.008018572484330876 0.0033844506844866893 -0.0032407613798985575
                    angularVelocity -0.12173214821551995 -0.04329131373343117 0.048308109565644845
                  }
                }
              ]
              name "leg4_right_leg_link1"
              boundingObject USE right_leg_link1
              physics Physics {
                density -1
                mass 0.07171
                centerOfMass [
                  0.025933 -0.003053 -0.022581
                ]
                inertiaMatrix [
                  5.19971e-05 9.90141e-05 5.4006e-05
                  -3.20773e-06 4.50866e-05 -2.72931e-06
                ]
              }
              linearVelocity -0.0077181107776013525 0.0015521974938656085 -0.004125482216395679
              angularVelocity -0.12173214804134644 -0.04329131383968619 0.048308109737044955
            }
          }
        ]
        name "leg4_right_leg_base_link"
        boundingObject USE right_leg_base_link
        physics Physics {
          density -1
          mass 0.05169
          centerOfMass [
            0.021397 0.009944 -0.014892
          ]
          inertiaMatrix [
            4.24864e-05 4.41958e-05 4.49559e-05
            -1.98151e-05 -1.89033e-05 1.87489e-05
          ]
        }
        linearVelocity -0.00566119729091944 -0.0003429380210497279 -0.0015691690881862598
        angularVelocity -0.08329885810149952 -0.06689795848431276 0.048512124035705914
      }
    }
    DEF leg2_right HingeJoint {
      jointParameters HingeJointParameters {
        position -2.5897940487962234e-07
        axis 0 0 1
        anchor -0.03286 -0.047321 0
      }
      device [
        RotationalMotor {
          name "leg2_right_coxa"
          minPosition -3.14
          maxPosition 3.14
          maxTorque 100
        }
        PositionSensor {
          name "leg2_right_coxa_sensor"
        }
      ]
      endPoint Solid {
        translation -0.0328614541381559 -0.04732176388025127 7.709800100286179e-07
        rotation -1.5758925140269384e-07 -4.281678973950609e-08 -0.9999999999999868 2.5579000098551283
        children [
          Shape {
            appearance DEF leg5_right_leg_base_link_material PBRAppearance {
              roughness 1
              metalness 0
            }
            geometry USE right_leg_base_link
            castShadows FALSE
          }
          HingeJoint {
            jointParameters HingeJointParameters {
              position 0.42535043608650713
              axis 0.38825 -0.921554 -3e-06
              anchor 0.035081 -0.00574 -0.00929
            }
            device [
              RotationalMotor {
                name "leg2_right_femur"
                minPosition -3.14
                maxPosition 3.14
                maxTorque 100
              }
              PositionSensor {
                name "leg2_right_femur_sensor"
              }
            ]
            endPoint Solid {
              translation 0.035081529101798965 -0.005739782522705416 -0.009289991338604295
              rotation 0.8184256218185697 -0.22768615285735053 0.5275779727660231 1.9667569141709997
              children [
                Shape {
                  appearance DEF leg5_right_leg_link1_material PBRAppearance {
                    baseColor 0 0 0
                    roughness 1
                    metalness 0
                  }
                  geometry USE right_leg_link1
                }
                HingeJoint {
                  jointParameters HingeJointParameters {
                    position -0.2925150603345576
                    axis 0 0 1
                    anchor 0.061 0 0
                  }
                  device [
                    RotationalMotor {
                      name "leg2_right_tibia"
                      minPosition -3.14
                      maxPosition 3.14
                      maxTorque 100
                    }
                    PositionSensor {
                      name "leg2_right_tibia_sensor"
                    }
                  ]
                  endPoint Solid {
                    translation 0.061002452680782575 4.219612424588738e-06 4.770633767747761e-07
                    rotation 2.485225935572917e-08 1.3066045085485512e-08 -0.9999999999999996 2.069815078206972
                    children [
                      Shape {
                        appearance DEF leg5_right_leg_link2_material PBRAppearance {
                          baseColor 0 0 0
                          roughness 1
                          metalness 0
                        }
                        geometry USE right_leg_link2
                      }
                    ]
                    name "leg5_right_leg_link2"
                    boundingObject USE right_leg_link2
                    physics Physics {
                      density -1
                      mass 0.1
                      centerOfMass [
                        0.089594 0 -0.018644
                      ]
                      inertiaMatrix [
                        0.000142 0.000142 0.000142
                        0 0 0
                      ]
                    }
                    linearVelocity 0.004001796655068595 -0.011555169968502357 -0.019863966460351455
                    angularVelocity -0.20434767551731384 -0.10783171101274085 -0.028474378457562635
                  }
                }
                HingeJoint {
                  jointParameters HingeJointParameters {
                    position 9.960262036985856e-09
                    axis 0 0 -1
                    anchor 0.025507 0 0
                  }
                  device [
                    RotationalMotor {
                      name "leg5_right_leg_joint3"
                      minPosition -3.14
                      maxPosition 3.14
                      maxTorque 100
                    }
                    PositionSensor {
                      name "leg5_right_leg_joint3_sensor"
                    }
                  ]
                  endPoint Solid {
                    translation 0.025506998864848272 -8.079504181020818e-08 -1.6651124923328098e-11
                    rotation -1.8149828957413022e-08 1.0568232265556305e-09 0.9999999999999999 0.08819698856386393
                    children [
                      Shape {
                        appearance DEF leg5_right_leg_link3_material PBRAppearance {
                          roughness 1
                          metalness 0
                        }
                        geometry USE right_leg_link3
                      }
                      HingeJoint {
                        jointParameters HingeJointParameters {
                          position -4.940142220441869e-09
                          axis 0 0 -1.000003
                          anchor 0.0085 0.019 -0.01074
                        }
                        device [
                          RotationalMotor {
                            name "leg5_right_leg_joint4"
                            minPosition -3.14
                            maxPosition 3.14
                            maxTorque 100
                          }
                          PositionSensor {
                            name "leg5_right_leg_joint4_sensor"
                          }
                        ]
                        endPoint Solid {
                          translation 0.008499999139694646 0.018999991615267494 -0.01074000000173761
                          rotation -0.004610998479009952 -0.02488699080638786 -0.9996796368745485 0.36654500239013504
                          children [
                            Shape {
                              appearance DEF leg5_right_leg_link4_material PBRAppearance {
                                roughness 1
                                metalness 0
                              }
                              geometry USE right_leg_link4
                            }
                          ]
                          name "leg5_right_leg_link4"
                          boundingObject USE right_leg_link4
                          physics Physics {
                            density -1
                            mass 0.000537
                            centerOfMass [
                              0.015829 0.000934 -0.006825
                            ]
                            inertiaMatrix [
                              1.8438e-09 4.7249e-09 5.3635e-09
                              -4.6086e-19 8.7449e-13 -3.9428e-20
                            ]
                          }
                          linearVelocity -0.006266838281825613 0.004409094836691496 -0.009599367122783841
                          angularVelocity -0.05958780606935102 -0.059419883594836555 -0.028408029554495118
                        }
                      }
                    ]
                    name "leg5_right_leg_link3"
                    boundingObject USE right_leg_link3
                    physics Physics {
                      density -1
                      mass 0.004611
                      centerOfMass [
                        0.000404 0.014672 -0.020116
                      ]
                      inertiaMatrix [
                        1.552e-06 1.3255e-06 3.6852e-07
                        -8.5323e-09 8.9451e-10 7.5364e-08
                      ]
                    }
                    linearVelocity -0.005462579521364151 0.0031996759581602724 -0.008756648401272545
                    angularVelocity -0.05958780603373254 -0.05941988358977284 -0.028408029544539002
                  }
                }
              ]
              name "leg5_right_leg_link1"
              boundingObject USE right_leg_link1
              physics Physics {
                density -1
                mass 0.07171
                centerOfMass [
                  0.025933 -0.003053 -0.022581
                ]
                inertiaMatrix [
                  5.19971e-05 9.90141e-05 5.4006e-05
                  -3.20773e-06 4.50866e-05 -2.72931e-06
                ]
              }
              linearVelocity -0.004518672094082139 0.0028387433608890018 -0.009981709706831732
              angularVelocity -0.05958780269771794 -0.05941988259488465 -0.028408029401295457
            }
          }
        ]
        name "leg5_right_leg_base_link"
        boundingObject USE right_leg_base_link
        physics Physics {
          density -1
          mass 0.05169
          centerOfMass [
            0.021397 0.009944 -0.014892
          ]
          inertiaMatrix [
            4.24864e-05 4.41958e-05 4.49559e-05
            -1.98151e-05 -1.89033e-05 1.87489e-05
          ]
        }
        linearVelocity -0.0036429638728106865 0.0009436341862700567 -0.007875232962047255
        angularVelocity -0.08313076039336412 -0.06729310057258124 -0.028418853004883775
      }
    }
    DEF leg1_right HingeJoint {
      jointParameters HingeJointParameters {
        position -0.17377748783512875
        axis 0 0 1
        anchor 0.024551 -0.052118 0
      }
      device [
        RotationalMotor {
          name "leg1_right_coxa"
          minPosition -3.14
          maxPosition 3.14
          maxTorque 100
        }
        PositionSensor {
          name "leg1_right_coxa_sensor"
        }
      ]
      endPoint Solid {
        translation 0.02455064401214356 -0.05211836268607614 -1.301507435241818e-06
        rotation 8.578439036146378e-09 4.639711699639851e-08 -0.999999999999999 1.684477498963507
        children [
          Shape {
            appearance DEF leg6_right_leg_base_link_material PBRAppearance {
              roughness 1
              metalness 0
            }
            geometry USE right_leg_base_link
            castShadows FALSE
          }
          HingeJoint {
            jointParameters HingeJointParameters {
              position -0.14812048997439115
              axis 0.38825 -0.921554 -3e-06
              anchor 0.035081 -0.00574 -0.00929
            }
            device [
              RotationalMotor {
                name "leg1_right_femur"
                minPosition -3.14
                maxPosition 3.14
                maxTorque 100
              }
              PositionSensor {
                name "leg1_right_femur_sensor"
              }
            ]
            endPoint Solid {
              translation 0.03508141056925058 -0.005740159619786841 -0.009290365067901565
              rotation 0.9365209993111926 0.01442039458712256 0.35031481565745476 1.7111474246645115
              children [
                Shape {
                  appearance DEF leg6_right_leg_link1_material PBRAppearance {
                    baseColor 0 0 0
                    roughness 1
                    metalness 0
                  }
                  geometry USE right_leg_link1
                }
                HingeJoint {
                  jointParameters HingeJointParameters {
                    position 0.5883552755139841
                    axis 0 0 1
                    anchor 0.061 0 0
                  }
                  device [
                    RotationalMotor {
                      name "leg1_right_tibia"
                      minPosition -3.14
                      maxPosition 3.14
                      maxTorque 100
                    }
                    PositionSensor {
                      name "leg1_right_tibia_sensor"
                    }
                  ]
                  endPoint Solid {
                    translation 0.06100004312239541 1.3048906051311871e-08 1.1559992740828317e-07
                    rotation -4.59663213969737e-09 -8.13293138195948e-09 -1 1.1889447086875884
                    children [
                      Shape {
                        appearance DEF leg6_right_leg_link2_material PBRAppearance {
                          baseColor 0 0 0
                          roughness 1
                          metalness 0
                        }
                        geometry USE right_leg_link2
                      }
                    ]
                    name "leg6_right_leg_link2"
                    boundingObject USE right_leg_link2
                    physics Physics {
                      density -1
                      mass 0.1
                      centerOfMass [
                        0.089594 0 -0.018644
                      ]
                      inertiaMatrix [
                        0.000142 0.000142 0.000142
                        0 0 0
                      ]
                    }
                    linearVelocity -0.004140497846410937 0.01692658008894647 -0.012430196375354984
                    angularVelocity -0.031519425794943726 -0.03041942857776278 -0.13044821384094674
                  }
                }
                HingeJoint {
                  jointParameters HingeJointParameters {
                    position -1.2652564435594453e-08
                    axis 0 0 -1
                    anchor 0.025507 0 0
                  }
                  device [
                    RotationalMotor {
                      name "leg6_right_leg_joint3"
                      minPosition -3.14
                      maxPosition 3.14
                      maxTorque 100
                    }
                    PositionSensor {
                      name "leg6_right_leg_joint3_sensor"
                    }
                  ]
                  endPoint Solid {
                    translation 0.025506998798263132 -8.079396822343098e-08 1.3253678710078987e-10
                    rotation -1.8123988124433266e-08 1.0680586191897985e-09 0.9999999999999998 0.08819701396367381
                    children [
                      Shape {
                        appearance DEF leg6_right_leg_link3_material PBRAppearance {
                          roughness 1
                          metalness 0
                        }
                        geometry USE right_leg_link3
                      }
                      HingeJoint {
                        jointParameters HingeJointParameters {
                          position 1.7010300230397018e-09
                          axis 0 0 -1.000003
                          anchor 0.0085 0.019 -0.01074
                        }
                        device [
                          RotationalMotor {
                            name "leg6_right_leg_joint4"
                            minPosition -3.14
                            maxPosition 3.14
                            maxTorque 100
                          }
                          PositionSensor {
                            name "leg6_right_leg_joint4_sensor"
                          }
                        ]
                        endPoint Solid {
                          translation 0.008499999132787064 0.018999991615989892 -0.010739999986175613
                          rotation -0.004610998479103505 -0.02488699035870118 -0.9996796368856932 0.36654500884460334
                          children [
                            Shape {
                              appearance DEF leg6_right_leg_link4_material PBRAppearance {
                                roughness 1
                                metalness 0
                              }
                              geometry USE right_leg_link4
                            }
                          ]
                          name "leg6_right_leg_link4"
                          boundingObject USE right_leg_link4
                          physics Physics {
                            density -1
                            mass 0.000537
                            centerOfMass [
                              0.015829 0.000934 -0.006825
                            ]
                            inertiaMatrix [
                              1.8438e-09 4.7249e-09 5.3635e-09
                              -4.6086e-19 8.7449e-13 -3.9428e-20
                            ]
                          }
                          linearVelocity -0.006611551072780421 0.012205889283653792 -0.012905786561020703
                          angularVelocity -0.09946366319754074 -0.10966750469008028 -0.10517145718956118
                        }
                      }
                    ]
                    name "leg6_right_leg_link3"
                    boundingObject USE right_leg_link3
                    physics Physics {
                      density -1
                      mass 0.004611
                      centerOfMass [
                        0.000404 0.014672 -0.020116
                      ]
                      inertiaMatrix [
                        1.552e-06 1.3255e-06 3.6852e-07
                        -8.5323e-09 8.9451e-10 7.5364e-08
                      ]
                    }
                    linearVelocity -0.006627241750763454 0.009275272201469868 -0.009835202879295818
                    angularVelocity -0.09946366319857362 -0.10966750470955557 -0.10517145717342384
                  }
                }
              ]
              name "leg6_right_leg_link1"
              boundingObject USE right_leg_link1
              physics Physics {
                density -1
                mass 0.07171
                centerOfMass [
                  0.025933 -0.003053 -0.022581
                ]
                inertiaMatrix [
                  5.19971e-05 9.90141e-05 5.4006e-05
                  -3.20773e-06 4.50866e-05 -2.72931e-06
                ]
              }
              linearVelocity -0.004823262942749979 0.008512294127888186 -0.010745801003938488
              angularVelocity -0.09946366271746299 -0.10966750409219446 -0.10517145711378961
            }
          }
        ]
        name "leg6_right_leg_base_link"
        boundingObject USE right_leg_base_link
        physics Physics {
          density -1
          mass 0.05169
          centerOfMass [
            0.021397 0.009944 -0.014892
          ]
          inertiaMatrix [
            4.24864e-05 4.41958e-05 4.49559e-05
            -1.98151e-05 -1.89033e-05 1.87489e-05
          ]
        }
        linearVelocity -0.004681543814239198 0.004180878134489288 -0.006753851422039087
        angularVelocity -0.08296414008827664 -0.06768964853551226 -0.10535096900374762
      }
    }
  ]
  name "Spider"
  boundingObject USE base_link
  physics Physics {
    density -1
    mass 0.42388
    centerOfMass [
      -5.5e-05 9.9e-05 -0.018675
    ]
    inertiaMatrix [
      0.000707768 0.000694017 0.00111424
      1.1258e-07 1.521e-08 -7.61e-09
    ]
  }
  controller "tripod gait"
  controllerArgs [
    ""
  ]
  linearVelocity -0.005609258192741596 -6.34303303020103e-05 0.0002605323179274144
  angularVelocity -0.08313079209337691 -0.06729311072375521 -0.02841883960817541
}
