#VRML_SIM R2025a utf8
# license: Apache License 2.0
# license url: http://www.apache.org/licenses/LICENSE-2.0
# This is a proto file for Webots for the BodyDescription
# Extracted from: C:\Users\bj\iCloudDrive\Desktop\windows文件\科研\spider\body_description\urdf\body_description.urdf

PROTO BodyDescription [
  field  SFVec3f     translation     0 0 0
  field  SFRotation  rotation        0 0 1 0
  field  SFString    name            "BodyDescription"  # Is `Robot.name`.
  field  SFString    controller      "void"             # Is `Robot.controller`.
  field  MFString    controllerArgs  []                 # Is `Robot.controllerArgs`.
  field  SFString    customData      ""                 # Is `Robot.customData`.
  field  SFBool      supervisor      FALSE              # Is `Robot.supervisor`.
  field  SFBool      synchronization TRUE               # Is `Robot.synchronization`.
  field  SFBool      selfCollision   FALSE              # Is `Robot.selfCollision`.
]
{
  Robot {
    translation IS translation
    rotation IS rotation
    controller IS controller
    controllerArgs IS controllerArgs
    customData IS customData
    supervisor IS supervisor
    synchronization IS synchronization
    selfCollision IS selfCollision
    children [
      Shape {
        appearance DEF base_link_material PBRAppearance {
          baseColor 0.792160 0.819610 0.933330
          roughness 1.000000
          metalness 0
        }
        geometry DEF base_link Mesh {
          url "C:/Users/bj/iCloudDrive/Desktop/windows file/research/spider/webots/meshes/base_link.STL"
        }
      }
      HingeJoint {
        jointParameters HingeJointParameters {
          axis 0.000000 0.000000 1.000000
          anchor 0.057411 -0.004797 0.000000
        }
        device [
          RotationalMotor {
            name "leg1_joint"
            maxVelocity 10.0
            minPosition -3.14
            maxPosition 3.14
            maxTorque 100.0
          }
          PositionSensor {
            name "leg1_joint_sensor"
          }
        ]
        endPoint Solid {
          translation 0.057411 -0.004797 0.000000
          rotation 0.000000 0.000000 -1.000000 0.423478
          children [
            Shape {
              appearance DEF leg1_left_leg_base_link_material PBRAppearance {
                baseColor 0.792160 0.819610 0.933330
                roughness 1.000000
                metalness 0
              }
              geometry DEF left_leg_base_link Mesh {
                url "C:/Users/bj/iCloudDrive/Desktop/windows file/research/spider/webots/meshes/left_leg_base_link.STL"
              }
            }
            HingeJoint {
              jointParameters HingeJointParameters {
                axis -0.336567 0.941659 -0.000004
                anchor 0.021980 0.027937 -0.009290
              }
              device [
                RotationalMotor {
                  name "leg1_left_leg_joint1"
                  maxVelocity 10.0
                  minPosition -3.14
                  maxPosition 3.14
                  maxTorque 100.0
                }
                PositionSensor {
                  name "leg1_left_leg_joint1_sensor"
                }
              ]
              endPoint Solid {
                translation 0.021980 0.027937 -0.009290
                rotation -0.947482 -0.319288 0.018230 1.571132
                children [
                  Shape {
                    appearance DEF leg1_left_leg_link1_material PBRAppearance {
                      baseColor 0.792160 0.819610 0.933330
                      roughness 1.000000
                      metalness 0
                    }
                    geometry DEF left_leg_link1 Mesh {
                      url "C:/Users/bj/iCloudDrive/Desktop/windows file/research/spider/webots/meshes/left_leg_link1.STL"
                    }
                  }
                  HingeJoint {
                    jointParameters HingeJointParameters {
                      axis 0.000000 0.000000 1.000000
                      anchor 0.061000 0.000000 0.000000
                    }
                    device [
                      RotationalMotor {
                        name "leg1_left_leg_joint2"
                        maxVelocity 10.0
                        minPosition -3.14
                        maxPosition 3.14
                        maxTorque 100.0
                      }
                      PositionSensor {
                        name "leg1_left_leg_joint2_sensor"
                      }
                    ]
                    endPoint Solid {
                      translation 0.061000 0.000000 0.000000
                      rotation 0.000000 0.000000 1.000000 1.548100
                      children [
                        Shape {
                          appearance DEF leg1_left_leg_link2_material PBRAppearance {
                            baseColor 0.792160 0.819610 0.933330
                            roughness 1.000000
                            metalness 0
                          }
                          geometry DEF left_leg_link2 Mesh {
                            url "C:/Users/bj/iCloudDrive/Desktop/windows file/research/spider/webots/meshes/left_leg_link2.STL"
                          }
                        }
                      ]
                      name "leg1_left_leg_link2"
                      boundingObject Capsule {
                        radius 0.01
                        height 0.14232
                      }
                      physics Physics {
                        density -1
                        mass 0.014281
                        centerOfMass [ 0.089594 -0.000000 -0.018644 ]
                        inertiaMatrix [
                          3.699200e-07 5.568900e-06 5.612900e-06
                          5.492500e-22 8.536500e-22 8.470300e-22
                        ]
                      }
                    }
                  }
                  HingeJoint {
                    jointParameters HingeJointParameters {
                      axis 0.000000 0.000000 -1.000000
                      anchor 0.025500 0.000000 0.000000
                    }
                    device [
                      RotationalMotor {
                        name "leg1_left_leg_joint3"
                        maxVelocity 10.0
                        minPosition -3.14
                        maxPosition 3.14
                        maxTorque 100.0
                      }
                      PositionSensor {
                        name "leg1_left_leg_joint3_sensor"
                      }
                    ]
                    endPoint Solid {
                      translation 0.025500 0.000000 0.000000
                      rotation 0.000000 0.000000 -1.000000 0.211720
                      children [
                        Shape {
                          appearance DEF leg1_left_leg_link3_material PBRAppearance {
                            baseColor 0.792160 0.819610 0.933330
                            roughness 1.000000
                            metalness 0
                          }
                          geometry DEF left_leg_link3 Mesh {
                            url "C:/Users/bj/iCloudDrive/Desktop/windows file/research/spider/webots/meshes/left_leg_link3.STL"
                          }
                        }
                        HingeJoint {
                          jointParameters HingeJointParameters {
                            axis -0.008081 -0.004450 -0.999957
                            anchor 0.008493 -0.020001 0.000000
                          }
                          device [
                            RotationalMotor {
                              name "leg1_left_leg_joint4"
                              maxVelocity 10.0
                              minPosition -3.14
                              maxPosition 3.14
                              maxTorque 100.0
                            }
                            PositionSensor {
                              name "leg1_left_leg_joint4_sensor"
                            }
                          ]
                          endPoint Solid {
                            translation 0.008493 -0.020001 0.000000
                            rotation -0.004612 0.017938 0.999828 0.503403
                            children [
                              Shape {
                                appearance DEF leg1_left_leg_link4_material PBRAppearance {
                                  baseColor 0.792160 0.819610 0.933330
                                  roughness 1.000000
                                  metalness 0
                                }
                                geometry DEF left_leg_link4 Mesh {
                                  url "C:/Users/bj/iCloudDrive/Desktop/windows file/research/spider/webots/meshes/left_leg_link4.STL"
                                }
                              }
                            ]
                            name "leg1_left_leg_link4"
                            boundingObject USE left_leg_link4
                            physics Physics {
                              density -1
                              mass 0.000537
                              centerOfMass [ 0.016434 0.000000 -0.019911 ]
                              inertiaMatrix [
                                1.843800e-09 4.724900e-09 5.363500e-09
                                4.617600e-20 -8.744900e-13 -1.855200e-20
                              ]
                            }
                          }
                        }
                      ]
                      name "leg1_left_leg_link3"
                      boundingObject USE left_leg_link3
                      physics Physics {
                        density -1
                        mass 0.004264
                        centerOfMass [ 0.000431 -0.015395 -0.018260 ]
                        inertiaMatrix [
                          1.535300e-06 1.323500e-06 3.507300e-07
                          8.532300e-09 8.945100e-10 -7.429600e-08
                        ]
                      }
                    }
                  }
                ]
                name "leg1_left_leg_link1"
                boundingObject USE left_leg_link1
                physics Physics {
                  density -1
                  mass 0.017021
                  centerOfMass [ 0.025933 0.003053 -0.022581 ]
                  inertiaMatrix [
                    2.090800e-06 3.603400e-06 2.931400e-06
                    1.356500e-08 -2.311800e-07 1.316400e-07
                  ]
                }
              }
            }
          ]
          name "leg1_left_leg_base_link"
          boundingObject USE left_leg_base_link
          physics Physics {
            density -1
            mass 0.011294
            centerOfMass [ 0.022492 0.007129 -0.014892 ]
            inertiaMatrix [
              1.708100e-06 1.786100e-06 1.171600e-06
              8.314600e-08 -1.753100e-07 -1.213000e-08
            ]
          }
        }
      }
      HingeJoint {
        jointParameters HingeJointParameters {
          axis 0.000000 0.000000 1.000000
          anchor 0.032860 0.047321 0.000000
        }
        device [
          RotationalMotor {
            name "leg2_joint"
            maxVelocity 10.0
            minPosition -3.14
            maxPosition 3.14
            maxTorque 100.0
          }
          PositionSensor {
            name "leg2_joint_sensor"
          }
        ]
        endPoint Solid {
          translation 0.032860 0.047321 0.000000
          rotation 0.000000 0.000000 1.000000 0.623720
          children [
            Shape {
              appearance DEF leg2_left_leg_base_link_material PBRAppearance {
                baseColor 0.792160 0.819610 0.933330
                roughness 1.000000
                metalness 0
              }
              geometry USE left_leg_base_link
            }
            HingeJoint {
              jointParameters HingeJointParameters {
                axis -0.336567 0.941659 -0.000004
                anchor 0.021980 0.027937 -0.009290
              }
              device [
                RotationalMotor {
                  name "leg2_left_leg_joint1"
                  maxVelocity 10.0
                  minPosition -3.14
                  maxPosition 3.14
                  maxTorque 100.0
                }
                PositionSensor {
                  name "leg2_left_leg_joint1_sensor"
                }
              ]
              endPoint Solid {
                translation 0.021980 0.027937 -0.009290
                rotation -0.947482 -0.319288 0.018230 1.571132
                children [
                  Shape {
                    appearance DEF leg2_left_leg_link1_material PBRAppearance {
                      baseColor 0.792160 0.819610 0.933330
                      roughness 1.000000
                      metalness 0
                    }
                    geometry USE left_leg_link1
                  }
                  HingeJoint {
                    jointParameters HingeJointParameters {
                      axis 0.000000 0.000000 1.000000
                      anchor 0.061000 0.000000 0.000000
                    }
                    device [
                      RotationalMotor {
                        name "leg2_left_leg_joint2"
                        maxVelocity 10.0
                        minPosition -3.14
                        maxPosition 3.14
                        maxTorque 100.0
                      }
                      PositionSensor {
                        name "leg2_left_leg_joint2_sensor"
                      }
                    ]
                    endPoint Solid {
                      translation 0.061000 0.000000 0.000000
                      rotation 0.000000 0.000000 1.000000 1.548100
                      children [
                        Shape {
                          appearance DEF leg2_left_leg_link2_material PBRAppearance {
                            baseColor 0.792160 0.819610 0.933330
                            roughness 1.000000
                            metalness 0
                          }
                          geometry USE left_leg_link2
                        }
                      ]
                      name "leg2_left_leg_link2"
                      boundingObject Capsule {
                        radius 0.01
                        height 0.14232
                      }
                      physics Physics {
                        density -1
                        mass 0.014281
                        centerOfMass [ 0.089594 -0.000000 -0.018644 ]
                        inertiaMatrix [
                          3.699200e-07 5.568900e-06 5.612900e-06
                          5.492500e-22 8.536500e-22 8.470300e-22
                        ]
                      }
                    }
                  }
                  HingeJoint {
                    jointParameters HingeJointParameters {
                      axis 0.000000 0.000000 -1.000000
                      anchor 0.025500 0.000000 0.000000
                    }
                    device [
                      RotationalMotor {
                        name "leg2_left_leg_joint3"
                        maxVelocity 10.0
                        minPosition -3.14
                        maxPosition 3.14
                        maxTorque 100.0
                      }
                      PositionSensor {
                        name "leg2_left_leg_joint3_sensor"
                      }
                    ]
                    endPoint Solid {
                      translation 0.025500 0.000000 0.000000
                      rotation 0.000000 0.000000 -1.000000 0.211720
                      children [
                        Shape {
                          appearance DEF leg2_left_leg_link3_material PBRAppearance {
                            baseColor 0.792160 0.819610 0.933330
                            roughness 1.000000
                            metalness 0
                          }
                          geometry USE left_leg_link3
                        }
                        HingeJoint {
                          jointParameters HingeJointParameters {
                            axis -0.008081 -0.004450 -0.999957
                            anchor 0.008493 -0.020001 0.000000
                          }
                          device [
                            RotationalMotor {
                              name "leg2_left_leg_joint4"
                              maxVelocity 10.0
                              minPosition -3.14
                              maxPosition 3.14
                              maxTorque 100.0
                            }
                            PositionSensor {
                              name "leg2_left_leg_joint4_sensor"
                            }
                          ]
                          endPoint Solid {
                            translation 0.008493 -0.020001 0.000000
                            rotation -0.004612 0.017938 0.999828 0.503403
                            children [
                              Shape {
                                appearance DEF leg2_left_leg_link4_material PBRAppearance {
                                  baseColor 0.792160 0.819610 0.933330
                                  roughness 1.000000
                                  metalness 0
                                }
                                geometry USE left_leg_link4
                              }
                            ]
                            name "leg2_left_leg_link4"
                            boundingObject USE left_leg_link4
                            physics Physics {
                              density -1
                              mass 0.000537
                              centerOfMass [ 0.016434 0.000000 -0.019911 ]
                              inertiaMatrix [
                                1.843800e-09 4.724900e-09 5.363500e-09
                                4.617600e-20 -8.744900e-13 -1.855200e-20
                              ]
                            }
                          }
                        }
                      ]
                      name "leg2_left_leg_link3"
                      boundingObject USE left_leg_link3
                      physics Physics {
                        density -1
                        mass 0.004264
                        centerOfMass [ 0.000431 -0.015395 -0.018260 ]
                        inertiaMatrix [
                          1.535300e-06 1.323500e-06 3.507300e-07
                          8.532300e-09 8.945100e-10 -7.429600e-08
                        ]
                      }
                    }
                  }
                ]
                name "leg2_left_leg_link1"
                boundingObject USE left_leg_link1
                physics Physics {
                  density -1
                  mass 0.017021
                  centerOfMass [ 0.025933 0.003053 -0.022581 ]
                  inertiaMatrix [
                    2.090800e-06 3.603400e-06 2.931400e-06
                    1.356500e-08 -2.311800e-07 1.316400e-07
                  ]
                }
              }
            }
          ]
          name "leg2_left_leg_base_link"
          boundingObject USE left_leg_base_link
          physics Physics {
            density -1
            mass 0.011294
            centerOfMass [ 0.022492 0.007129 -0.014892 ]
            inertiaMatrix [
              1.708100e-06 1.786100e-06 1.171600e-06
              8.314600e-08 -1.753100e-07 -1.213000e-08
            ]
          }
        }
      }
      HingeJoint {
        jointParameters HingeJointParameters {
          axis 0.000000 0.000000 1.000000
          anchor -0.024551 0.052118 0.000000
        }
        device [
          RotationalMotor {
            name "leg3_joint"
            maxVelocity 10.0
            minPosition -3.14
            maxPosition 3.14
            maxTorque 100.0
          }
          PositionSensor {
            name "leg3_joint_sensor"
          }
        ]
        endPoint Solid {
          translation -0.024551 0.052118 0.000000
          rotation 0.000000 0.000000 1.000000 1.670900
          children [
            Shape {
              appearance DEF leg3_left_leg_base_link_material PBRAppearance {
                baseColor 0.792160 0.819610 0.933330
                roughness 1.000000
                metalness 0
              }
              geometry USE left_leg_base_link
            }
            HingeJoint {
              jointParameters HingeJointParameters {
                axis -0.336567 0.941659 -0.000004
                anchor 0.021980 0.027937 -0.009290
              }
              device [
                RotationalMotor {
                  name "leg3_left_leg_joint1"
                  maxVelocity 10.0
                  minPosition -3.14
                  maxPosition 3.14
                  maxTorque 100.0
                }
                PositionSensor {
                  name "leg3_left_leg_joint1_sensor"
                }
              ]
              endPoint Solid {
                translation 0.021980 0.027937 -0.009290
                rotation -0.947482 -0.319288 0.018230 1.571132
                children [
                  Shape {
                    appearance DEF leg3_left_leg_link1_material PBRAppearance {
                      baseColor 0.792160 0.819610 0.933330
                      roughness 1.000000
                      metalness 0
                    }
                    geometry USE left_leg_link1
                  }
                  HingeJoint {
                    jointParameters HingeJointParameters {
                      axis 0.000000 0.000000 1.000000
                      anchor 0.061000 0.000000 0.000000
                    }
                    device [
                      RotationalMotor {
                        name "leg3_left_leg_joint2"
                        maxVelocity 10.0
                        minPosition -3.14
                        maxPosition 3.14
                        maxTorque 100.0
                      }
                      PositionSensor {
                        name "leg3_left_leg_joint2_sensor"
                      }
                    ]
                    endPoint Solid {
                      translation 0.061000 0.000000 0.000000
                      rotation 0.000000 0.000000 1.000000 1.548100
                      children [
                        Shape {
                          appearance DEF leg3_left_leg_link2_material PBRAppearance {
                            baseColor 0.792160 0.819610 0.933330
                            roughness 1.000000
                            metalness 0
                          }
                          geometry USE left_leg_link2
                        }
                      ]
                      name "leg3_left_leg_link2"
                      boundingObject Capsule {
                        radius 0.01
                        height 0.14232
                      }
                      physics Physics {
                        density -1
                        mass 0.014281
                        centerOfMass [ 0.089594 -0.000000 -0.018644 ]
                        inertiaMatrix [
                          3.699200e-07 5.568900e-06 5.612900e-06
                          5.492500e-22 8.536500e-22 8.470300e-22
                        ]
                      }
                    }
                  }
                  HingeJoint {
                    jointParameters HingeJointParameters {
                      axis 0.000000 0.000000 -1.000000
                      anchor 0.025500 0.000000 0.000000
                    }
                    device [
                      RotationalMotor {
                        name "leg3_left_leg_joint3"
                        maxVelocity 10.0
                        minPosition -3.14
                        maxPosition 3.14
                        maxTorque 100.0
                      }
                      PositionSensor {
                        name "leg3_left_leg_joint3_sensor"
                      }
                    ]
                    endPoint Solid {
                      translation 0.025500 0.000000 0.000000
                      rotation 0.000000 0.000000 -1.000000 0.211720
                      children [
                        Shape {
                          appearance DEF leg3_left_leg_link3_material PBRAppearance {
                            baseColor 0.792160 0.819610 0.933330
                            roughness 1.000000
                            metalness 0
                          }
                          geometry USE left_leg_link3
                        }
                        HingeJoint {
                          jointParameters HingeJointParameters {
                            axis -0.008081 -0.004450 -0.999957
                            anchor 0.008493 -0.020001 0.000000
                          }
                          device [
                            RotationalMotor {
                              name "leg3_left_leg_joint4"
                              maxVelocity 10.0
                              minPosition -3.14
                              maxPosition 3.14
                              maxTorque 100.0
                            }
                            PositionSensor {
                              name "leg3_left_leg_joint4_sensor"
                            }
                          ]
                          endPoint Solid {
                            translation 0.008493 -0.020001 0.000000
                            rotation -0.004612 0.017938 0.999828 0.503403
                            children [
                              Shape {
                                appearance DEF leg3_left_leg_link4_material PBRAppearance {
                                  baseColor 0.792160 0.819610 0.933330
                                  roughness 1.000000
                                  metalness 0
                                }
                                geometry USE left_leg_link4
                              }
                            ]
                            name "leg3_left_leg_link4"
                            boundingObject USE left_leg_link4
                            physics Physics {
                              density -1
                              mass 0.000537
                              centerOfMass [ 0.016434 0.000000 -0.019911 ]
                              inertiaMatrix [
                                1.843800e-09 4.724900e-09 5.363500e-09
                                4.617600e-20 -8.744900e-13 -1.855200e-20
                              ]
                            }
                          }
                        }
                      ]
                      name "leg3_left_leg_link3"
                      boundingObject USE left_leg_link3
                      physics Physics {
                        density -1
                        mass 0.004264
                        centerOfMass [ 0.000431 -0.015395 -0.018260 ]
                        inertiaMatrix [
                          1.535300e-06 1.323500e-06 3.507300e-07
                          8.532300e-09 8.945100e-10 -7.429600e-08
                        ]
                      }
                    }
                  }
                ]
                name "leg3_left_leg_link1"
                boundingObject USE left_leg_link1
                physics Physics {
                  density -1
                  mass 0.017021
                  centerOfMass [ 0.025933 0.003053 -0.022581 ]
                  inertiaMatrix [
                    2.090800e-06 3.603400e-06 2.931400e-06
                    1.356500e-08 -2.311800e-07 1.316400e-07
                  ]
                }
              }
            }
          ]
          name "leg3_left_leg_base_link"
          boundingObject USE left_leg_base_link
          physics Physics {
            density -1
            mass 0.011294
            centerOfMass [ 0.022492 0.007129 -0.014892 ]
            inertiaMatrix [
              1.708100e-06 1.786100e-06 1.171600e-06
              8.314600e-08 -1.753100e-07 -1.213000e-08
            ]
          }
        }
      }
      HingeJoint {
        jointParameters HingeJointParameters {
          axis 0.000000 0.000000 1.000000
          anchor -0.057411 0.004797 0.000000
        }
        device [
          RotationalMotor {
            name "leg4_joint"
            maxVelocity 10.0
            minPosition -3.14
            maxPosition 3.14
            maxTorque 100.0
          }
          PositionSensor {
            name "leg4_joint_sensor"
          }
        ]
        endPoint Solid {
          translation -0.057411 0.004797 0.000000
          rotation 0.000000 0.000000 1.000000 2.678100
          children [
            Shape {
              appearance DEF leg4_right_leg_base_link_material PBRAppearance {
                baseColor 0.792160 0.819610 0.933330
                roughness 1.000000
                metalness 0
              }
              geometry DEF right_leg_base_link Mesh {
                url "C:/Users/bj/iCloudDrive/Desktop/windows file/research/spider/webots/meshes/right_leg_base_link.STL"
              }
            }
            HingeJoint {
              jointParameters HingeJointParameters {
                axis 0.388250 -0.921554 -0.000003
                anchor 0.035081 -0.005740 -0.009290
              }
              device [
                RotationalMotor {
                  name "leg4_right_leg_joint1"
                  maxVelocity 10.0
                  minPosition -3.14
                  maxPosition 3.14
                  maxTorque 100.0
                }
                PositionSensor {
                  name "leg4_right_leg_joint1_sensor"
                }
              ]
              endPoint Solid {
                translation 0.035081 -0.005740 -0.009290
                rotation 0.913197 -0.053633 0.403974 1.767079
                children [
                  Shape {
                    appearance DEF leg4_right_leg_link1_material PBRAppearance {
                      baseColor 0.792160 0.819610 0.933330
                      roughness 1.000000
                      metalness 0
                    }
                    geometry DEF right_leg_link1 Mesh {
                      url "C:/Users/bj/iCloudDrive/Desktop/windows file/research/spider/webots/meshes/right_leg_link1.STL"
                    }
                  }
                  HingeJoint {
                    jointParameters HingeJointParameters {
                      axis 0.000000 -0.000000 1.000000
                      anchor 0.061000 0.000000 0.000000
                    }
                    device [
                      RotationalMotor {
                        name "leg4_right_leg_joint2"
                        maxVelocity 10.0
                        minPosition -3.14
                        maxPosition 3.14
                        maxTorque 100.0
                      }
                      PositionSensor {
                        name "leg4_right_leg_joint2_sensor"
                      }
                    ]
                    endPoint Solid {
                      translation 0.061000 0.000000 0.000000
                      rotation 0.000000 0.000000 -1.000000 1.777300
                      children [
                        Shape {
                          appearance DEF leg4_right_leg_link2_material PBRAppearance {
                            baseColor 0.792160 0.819610 0.933330
                            roughness 1.000000
                            metalness 0
                          }
                          geometry DEF right_leg_link2 Mesh {
                            url "C:/Users/bj/iCloudDrive/Desktop/windows file/research/spider/webots/meshes/right_leg_link2.STL"
                          }
                        }
                      ]
                      name "leg4_right_leg_link2"
                      boundingObject Capsule {
                        radius 0.01
                        height 0.14232
                      }
                      physics Physics {
                        density -1
                        mass 0.014281
                        centerOfMass [ 0.089594 -0.000000 -0.018644 ]
                        inertiaMatrix [
                          3.699200e-07 5.568900e-06 5.612900e-06
                          1.096500e-19 2.246600e-21 0.000000e+00
                        ]
                      }
                    }
                  }
                  HingeJoint {
                    jointParameters HingeJointParameters {
                      axis 0.000000 0.000000 -1.000000
                      anchor 0.025507 0.000000 0.000000
                    }
                    device [
                      RotationalMotor {
                        name "leg4_right_leg_joint3"
                        maxVelocity 10.0
                        minPosition -3.14
                        maxPosition 3.14
                        maxTorque 100.0
                      }
                      PositionSensor {
                        name "leg4_right_leg_joint3_sensor"
                      }
                    ]
                    endPoint Solid {
                      translation 0.025507 0.000000 0.000000
                      rotation 0.000000 0.000000 1.000000 0.088197
                      children [
                        Shape {
                          appearance DEF leg4_right_leg_link3_material PBRAppearance {
                            baseColor 0.792160 0.819610 0.933330
                            roughness 1.000000
                            metalness 0
                          }
                          geometry DEF right_leg_link3 Mesh {
                            url "C:/Users/bj/iCloudDrive/Desktop/windows file/research/spider/webots/meshes/right_leg_link3.STL"
                          }
                        }
                        HingeJoint {
                          jointParameters HingeJointParameters {
                            axis -0.000000 0.000000 -1.000003
                            anchor 0.008500 0.019000 -0.010740
                          }
                          device [
                            RotationalMotor {
                              name "leg4_right_leg_joint4"
                              maxVelocity 10.0
                              minPosition -3.14
                              maxPosition 3.14
                              maxTorque 100.0
                            }
                            PositionSensor {
                              name "leg4_right_leg_joint4_sensor"
                            }
                          ]
                          endPoint Solid {
                            translation 0.008500 0.019000 -0.010740
                            rotation -0.004611 -0.024887 -0.999680 0.366545
                            children [
                              Shape {
                                appearance DEF leg4_right_leg_link4_material PBRAppearance {
                                  baseColor 0.792160 0.819610 0.933330
                                  roughness 1.000000
                                  metalness 0
                                }
                                geometry DEF right_leg_link4 Mesh {
                                  url "C:/Users/bj/iCloudDrive/Desktop/windows file/research/spider/webots/meshes/right_leg_link4.STL"
                                }
                              }
                            ]
                            name "leg4_right_leg_link4"
                            boundingObject USE right_leg_link4
                            physics Physics {
                              density -1
                              mass 0.000537
                              centerOfMass [ 0.015829 0.000934 -0.006825 ]
                              inertiaMatrix [
                                1.843800e-09 4.724900e-09 5.363500e-09
                                -4.608600e-19 8.744900e-13 -3.942800e-20
                              ]
                            }
                          }
                        }
                      ]
                      name "leg4_right_leg_link3"
                      boundingObject USE right_leg_link3
                      physics Physics {
                        density -1
                        mass 0.004611
                        centerOfMass [ 0.000404 0.014672 -0.020116 ]
                        inertiaMatrix [
                          1.552000e-06 1.325500e-06 3.685200e-07
                          -8.532300e-09 8.945100e-10 7.536400e-08
                        ]
                      }
                    }
                  }
                ]
                name "leg4_right_leg_link1"
                boundingObject USE right_leg_link1
                physics Physics {
                  density -1
                  mass 0.017021
                  centerOfMass [ 0.025933 -0.003053 -0.022581 ]
                  inertiaMatrix [
                    2.090800e-06 3.603400e-06 2.931400e-06
                    -1.356500e-08 -2.311800e-07 -1.316400e-07
                  ]
                }
              }
            }
          ]
          name "leg4_right_leg_base_link"
          boundingObject USE right_leg_base_link
          physics Physics {
            density -1
            mass 0.011294
            centerOfMass [ 0.021397 0.009944 -0.014892 ]
            inertiaMatrix [
              1.826600e-06 1.667700e-06 1.171600e-06
              -4.609500e-08 -1.374200e-07 -1.095200e-07
            ]
          }
        }
      }
      HingeJoint {
        jointParameters HingeJointParameters {
          axis 0.000000 -0.000000 1.000000
          anchor -0.032860 -0.047321 0.000000
        }
        device [
          RotationalMotor {
            name "leg5_joint"
            maxVelocity 10.0
            minPosition -3.14
            maxPosition 3.14
            maxTorque 100.0
          }
          PositionSensor {
            name "leg5_joint_sensor"
          }
        ]
        endPoint Solid {
          translation -0.032860 -0.047321 0.000000
          rotation 0.000000 0.000000 -1.000000 2.557900
          children [
            Shape {
              appearance DEF leg5_right_leg_base_link_material PBRAppearance {
                baseColor 0.792160 0.819610 0.933330
                roughness 1.000000
                metalness 0
              }
              geometry USE right_leg_base_link
            }
            HingeJoint {
              jointParameters HingeJointParameters {
                axis 0.388250 -0.921554 -0.000003
                anchor 0.035081 -0.005740 -0.009290
              }
              device [
                RotationalMotor {
                  name "leg5_right_leg_joint1"
                  maxVelocity 10.0
                  minPosition -3.14
                  maxPosition 3.14
                  maxTorque 100.0
                }
                PositionSensor {
                  name "leg5_right_leg_joint1_sensor"
                }
              ]
              endPoint Solid {
                translation 0.035081 -0.005740 -0.009290
                rotation 0.913197 -0.053633 0.403974 1.767079
                children [
                  Shape {
                    appearance DEF leg5_right_leg_link1_material PBRAppearance {
                      baseColor 0.792160 0.819610 0.933330
                      roughness 1.000000
                      metalness 0
                    }
                    geometry USE right_leg_link1
                  }
                  HingeJoint {
                    jointParameters HingeJointParameters {
                      axis 0.000000 -0.000000 1.000000
                      anchor 0.061000 0.000000 0.000000
                    }
                    device [
                      RotationalMotor {
                        name "leg5_right_leg_joint2"
                        maxVelocity 10.0
                        minPosition -3.14
                        maxPosition 3.14
                        maxTorque 100.0
                      }
                      PositionSensor {
                        name "leg5_right_leg_joint2_sensor"
                      }
                    ]
                    endPoint Solid {
                      translation 0.061000 0.000000 0.000000
                      rotation 0.000000 0.000000 -1.000000 1.777300
                      children [
                        Shape {
                          appearance DEF leg5_right_leg_link2_material PBRAppearance {
                            baseColor 0.792160 0.819610 0.933330
                            roughness 1.000000
                            metalness 0
                          }
                          geometry USE right_leg_link2
                        }
                      ]
                      name "leg5_right_leg_link2"
                      boundingObject Capsule {
                        radius 0.01
                        height 0.14232
                      }
                      physics Physics {
                        density -1
                        mass 0.014281
                        centerOfMass [ 0.089594 -0.000000 -0.018644 ]
                        inertiaMatrix [
                          3.699200e-07 5.568900e-06 5.612900e-06
                          1.096500e-19 2.246600e-21 0.000000e+00
                        ]
                      }
                    }
                  }
                  HingeJoint {
                    jointParameters HingeJointParameters {
                      axis 0.000000 0.000000 -1.000000
                      anchor 0.025507 0.000000 0.000000
                    }
                    device [
                      RotationalMotor {
                        name "leg5_right_leg_joint3"
                        maxVelocity 10.0
                        minPosition -3.14
                        maxPosition 3.14
                        maxTorque 100.0
                      }
                      PositionSensor {
                        name "leg5_right_leg_joint3_sensor"
                      }
                    ]
                    endPoint Solid {
                      translation 0.025507 0.000000 0.000000
                      rotation 0.000000 0.000000 1.000000 0.088197
                      children [
                        Shape {
                          appearance DEF leg5_right_leg_link3_material PBRAppearance {
                            baseColor 0.792160 0.819610 0.933330
                            roughness 1.000000
                            metalness 0
                          }
                          geometry USE right_leg_link3
                        }
                        HingeJoint {
                          jointParameters HingeJointParameters {
                            axis -0.000000 0.000000 -1.000003
                            anchor 0.008500 0.019000 -0.010740
                          }
                          device [
                            RotationalMotor {
                              name "leg5_right_leg_joint4"
                              maxVelocity 10.0
                              minPosition -3.14
                              maxPosition 3.14
                              maxTorque 100.0
                            }
                            PositionSensor {
                              name "leg5_right_leg_joint4_sensor"
                            }
                          ]
                          endPoint Solid {
                            translation 0.008500 0.019000 -0.010740
                            rotation -0.004611 -0.024887 -0.999680 0.366545
                            children [
                              Shape {
                                appearance DEF leg5_right_leg_link4_material PBRAppearance {
                                  baseColor 0.792160 0.819610 0.933330
                                  roughness 1.000000
                                  metalness 0
                                }
                                geometry USE right_leg_link4
                              }
                            ]
                            name "leg5_right_leg_link4"
                            boundingObject USE right_leg_link4
                            physics Physics {
                              density -1
                              mass 0.000537
                              centerOfMass [ 0.015829 0.000934 -0.006825 ]
                              inertiaMatrix [
                                1.843800e-09 4.724900e-09 5.363500e-09
                                -4.608600e-19 8.744900e-13 -3.942800e-20
                              ]
                            }
                          }
                        }
                      ]
                      name "leg5_right_leg_link3"
                      boundingObject USE right_leg_link3
                      physics Physics {
                        density -1
                        mass 0.004611
                        centerOfMass [ 0.000404 0.014672 -0.020116 ]
                        inertiaMatrix [
                          1.552000e-06 1.325500e-06 3.685200e-07
                          -8.532300e-09 8.945100e-10 7.536400e-08
                        ]
                      }
                    }
                  }
                ]
                name "leg5_right_leg_link1"
                boundingObject USE right_leg_link1
                physics Physics {
                  density -1
                  mass 0.017021
                  centerOfMass [ 0.025933 -0.003053 -0.022581 ]
                  inertiaMatrix [
                    2.090800e-06 3.603400e-06 2.931400e-06
                    -1.356500e-08 -2.311800e-07 -1.316400e-07
                  ]
                }
              }
            }
          ]
          name "leg5_right_leg_base_link"
          boundingObject USE right_leg_base_link
          physics Physics {
            density -1
            mass 0.011294
            centerOfMass [ 0.021397 0.009944 -0.014892 ]
            inertiaMatrix [
              1.826600e-06 1.667700e-06 1.171600e-06
              -4.609500e-08 -1.374200e-07 -1.095200e-07
            ]
          }
        }
      }
      HingeJoint {
        jointParameters HingeJointParameters {
          axis 0.000000 0.000000 1.000000
          anchor 0.024551 -0.052118 0.000000
        }
        device [
          RotationalMotor {
            name "leg6_joint"
            maxVelocity 10.0
            minPosition -3.14
            maxPosition 3.14
            maxTorque 100.0
          }
          PositionSensor {
            name "leg6_joint_sensor"
          }
        ]
        endPoint Solid {
          translation 0.024551 -0.052118 0.000000
          rotation 0.000000 0.000000 -1.000000 1.510700
          children [
            Shape {
              appearance DEF leg6_right_leg_base_link_material PBRAppearance {
                baseColor 0.792160 0.819610 0.933330
                roughness 1.000000
                metalness 0
              }
              geometry USE right_leg_base_link
            }
            HingeJoint {
              jointParameters HingeJointParameters {
                axis 0.388250 -0.921554 -0.000003
                anchor 0.035081 -0.005740 -0.009290
              }
              device [
                RotationalMotor {
                  name "leg6_right_leg_joint1"
                  maxVelocity 10.0
                  minPosition -3.14
                  maxPosition 3.14
                  maxTorque 100.0
                }
                PositionSensor {
                  name "leg6_right_leg_joint1_sensor"
                }
              ]
              endPoint Solid {
                translation 0.035081 -0.005740 -0.009290
                rotation 0.913197 -0.053633 0.403974 1.767079
                children [
                  Shape {
                    appearance DEF leg6_right_leg_link1_material PBRAppearance {
                      baseColor 0.792160 0.819610 0.933330
                      roughness 1.000000
                      metalness 0
                    }
                    geometry USE right_leg_link1
                  }
                  HingeJoint {
                    jointParameters HingeJointParameters {
                      axis 0.000000 -0.000000 1.000000
                      anchor 0.061000 0.000000 0.000000
                    }
                    device [
                      RotationalMotor {
                        name "leg6_right_leg_joint2"
                        maxVelocity 10.0
                        minPosition -3.14
                        maxPosition 3.14
                        maxTorque 100.0
                      }
                      PositionSensor {
                        name "leg6_right_leg_joint2_sensor"
                      }
                    ]
                    endPoint Solid {
                      translation 0.061000 0.000000 0.000000
                      rotation 0.000000 0.000000 -1.000000 1.777300
                      children [
                        Shape {
                          appearance DEF leg6_right_leg_link2_material PBRAppearance {
                            baseColor 0.792160 0.819610 0.933330
                            roughness 1.000000
                            metalness 0
                          }
                          geometry USE right_leg_link2
                        }
                      ]
                      name "leg6_right_leg_link2"
                      boundingObject Capsule {
                        radius 0.01
                        height 0.14232
                      }
                      physics Physics {
                        density -1
                        mass 0.014281
                        centerOfMass [ 0.089594 -0.000000 -0.018644 ]
                        inertiaMatrix [
                          3.699200e-07 5.568900e-06 5.612900e-06
                          1.096500e-19 2.246600e-21 0.000000e+00
                        ]
                      }
                    }
                  }
                  HingeJoint {
                    jointParameters HingeJointParameters {
                      axis 0.000000 0.000000 -1.000000
                      anchor 0.025507 0.000000 0.000000
                    }
                    device [
                      RotationalMotor {
                        name "leg6_right_leg_joint3"
                        maxVelocity 10.0
                        minPosition -3.14
                        maxPosition 3.14
                        maxTorque 100.0
                      }
                      PositionSensor {
                        name "leg6_right_leg_joint3_sensor"
                      }
                    ]
                    endPoint Solid {
                      translation 0.025507 0.000000 0.000000
                      rotation 0.000000 0.000000 1.000000 0.088197
                      children [
                        Shape {
                          appearance DEF leg6_right_leg_link3_material PBRAppearance {
                            baseColor 0.792160 0.819610 0.933330
                            roughness 1.000000
                            metalness 0
                          }
                          geometry USE right_leg_link3
                        }
                        HingeJoint {
                          jointParameters HingeJointParameters {
                            axis -0.000000 0.000000 -1.000003
                            anchor 0.008500 0.019000 -0.010740
                          }
                          device [
                            RotationalMotor {
                              name "leg6_right_leg_joint4"
                              maxVelocity 10.0
                              minPosition -3.14
                              maxPosition 3.14
                              maxTorque 100.0
                            }
                            PositionSensor {
                              name "leg6_right_leg_joint4_sensor"
                            }
                          ]
                          endPoint Solid {
                            translation 0.008500 0.019000 -0.010740
                            rotation -0.004611 -0.024887 -0.999680 0.366545
                            children [
                              Shape {
                                appearance DEF leg6_right_leg_link4_material PBRAppearance {
                                  baseColor 0.792160 0.819610 0.933330
                                  roughness 1.000000
                                  metalness 0
                                }
                                geometry USE right_leg_link4
                              }
                            ]
                            name "leg6_right_leg_link4"
                            boundingObject USE right_leg_link4
                            physics Physics {
                              density -1
                              mass 0.000537
                              centerOfMass [ 0.015829 0.000934 -0.006825 ]
                              inertiaMatrix [
                                1.843800e-09 4.724900e-09 5.363500e-09
                                -4.608600e-19 8.744900e-13 -3.942800e-20
                              ]
                            }
                          }
                        }
                      ]
                      name "leg6_right_leg_link3"
                      boundingObject USE right_leg_link3
                      physics Physics {
                        density -1
                        mass 0.004611
                        centerOfMass [ 0.000404 0.014672 -0.020116 ]
                        inertiaMatrix [
                          1.552000e-06 1.325500e-06 3.685200e-07
                          -8.532300e-09 8.945100e-10 7.536400e-08
                        ]
                      }
                    }
                  }
                ]
                name "leg6_right_leg_link1"
                boundingObject USE right_leg_link1
                physics Physics {
                  density -1
                  mass 0.017021
                  centerOfMass [ 0.025933 -0.003053 -0.022581 ]
                  inertiaMatrix [
                    2.090800e-06 3.603400e-06 2.931400e-06
                    -1.356500e-08 -2.311800e-07 -1.316400e-07
                  ]
                }
              }
            }
          ]
          name "leg6_right_leg_base_link"
          boundingObject USE right_leg_base_link
          physics Physics {
            density -1
            mass 0.011294
            centerOfMass [ 0.021397 0.009944 -0.014892 ]
            inertiaMatrix [
              1.826600e-06 1.667700e-06 1.171600e-06
              -4.609500e-08 -1.374200e-07 -1.095200e-07
            ]
          }
        }
      }
    ]
    name IS name
    boundingObject USE base_link
    physics Physics {
      density -1
      mass 0.093105
      centerOfMass [ -0.000055 0.000099 -0.018675 ]
      inertiaMatrix [
        4.131100e-05 4.248000e-05 8.244700e-05
        1.260800e-06 4.332000e-08 -7.883200e-08
      ]
    }
  }
}
