<?xml version="1.0" ?>
<!-- =================================================================================== -->
<!-- |    This document was autogenerated by xacro from /home/liam/ros2_ws/src/body_description/urdf/body_description.xacro | -->
<!-- |    EDITING THIS FILE BY HAND IS NOT RECOMMENDED                                 | -->
<!-- =================================================================================== -->
<!-- This URDF was automatically created by SolidWorks to URDF Exporter! Originally created by Stephen Brawner (brawner@gmail.com) 
     Commit Version: 1.6.0-4-g7f85cfe  Build Version: 1.6.7995.38578
     For more information, please see http://wiki.ros.org/sw_urdf_exporter -->
<robot name="body_description">
  <link name="base_link">
    <inertial>
  <!-- 质心位置：从毫米转为米（÷1000） -->
  <origin rpy="0 0 0" xyz="0 0 -0.01618"/>
  <!-- 质量：从克转为千克（÷1000） -->
  <mass value="0.42388"/>
  <!-- 惯性张量：原始单位 g·mm² 换算到 kg·m²（×1e-9） -->
  <inertia 
    ixx="0.00070777"   
    ixy="0.0000001126"
    ixz="0.00000001521"
    iyy="0.00069402"  
    iyz="-0.00000000761"
    izz="0.00111424"  
  />
</inertial>

    <visual>
      <origin rpy="0 0 0" xyz="0 0 0"/>
      <geometry>
        <mesh filename="package://body_description/meshes/base_link.STL"/>
      </geometry>
      <material name="">
        <color rgba="0.79216 0.81961 0.93333 1"/>
      </material>
    </visual>
    <collision>
      <origin rpy="0 0 0" xyz="0 0 0"/>
      <geometry>
        <mesh filename="package://body_description/meshes/base_link.STL"/>
      </geometry>
    </collision>
  </link>
  <link name="leg1_left_leg_base_link">
    <inertial>
      <origin rpy="0 0 0" xyz="0.022492 0.007129 -0.014892"/>
      <mass value="0.011294"/>
      <inertia ixx="1.7081E-06" ixy="8.3146E-08" ixz="-1.7531E-07" iyy="1.7861E-06" iyz="-1.213E-08" izz="1.1716E-06"/>
    </inertial>
    <visual>
      <origin rpy="0 0 0" xyz="0 0 0"/>
      <geometry>
        <mesh filename="package://body_description/meshes/left_leg_base_link.STL"/>
      </geometry>
      <material name="">
        <color rgba="0.79216 0.81961 0.93333 1"/>
      </material>
    </visual>
    <collision>
      <origin rpy="0 0 0" xyz="0 0 0"/>
      <geometry>
        <mesh filename="package://body_description/meshes/left_leg_base_link.STL"/>
      </geometry>
    </collision>
  </link>
  <link name="leg1_left_leg_link1">
    <inertial>
      <origin rpy="0 0 0" xyz="0.025933 0.0030528 -0.022581"/>
      <mass value="0.017021"/>
      <inertia ixx="2.0908E-06" ixy="1.3565E-08" ixz="-2.3118E-07" iyy="3.6034E-06" iyz="1.3164E-07" izz="2.9314E-06"/>
    </inertial>
    <visual>
      <origin rpy="0 0 0" xyz="0 0 0"/>
      <geometry>
        <mesh filename="package://body_description/meshes/left_leg_link1.STL"/>
      </geometry>
      <material name="">
        <color rgba="0.79216 0.81961 0.93333 1"/>
      </material>
    </visual>
    <collision>
      <origin rpy="0 0 0" xyz="0 0 0"/>
      <geometry>
        <mesh filename="package://body_description/meshes/left_leg_link1.STL"/>
      </geometry>
    </collision>
  </link>
  <joint name="leg1_left_leg_joint1" type="revolute">
    <origin rpy="-1.5708 -0.3068 0.34327" xyz="0.02198 0.027937 -0.00929"/>
    <parent link="leg1_left_leg_base_link"/>
    <child link="leg1_left_leg_link1"/>
    <axis xyz="0 0 1"/>
    <limit effort="100" lower="-3.14" upper="3.14" velocity="10"/>
  </joint>
  <link name="leg1_left_leg_link2">
    <inertial>
      <origin rpy="0 0 0" xyz="0.089594 -7.9936E-15 -0.018644"/>
      <mass value="0.014281"/>
      <inertia ixx="3.6992E-07" ixy="5.4925E-22" ixz="8.5365E-22" iyy="5.5689E-06" iyz="8.4703E-22" izz="5.6129E-06"/>
    </inertial>
    <visual>
      <origin rpy="0 0 0" xyz="0 0 0"/>
      <geometry>
        <mesh filename="package://body_description/meshes/left_leg_link2.STL"/>
      </geometry>
      <material name="">
        <color rgba="0.79216 0.81961 0.93333 1"/>
      </material>
    </visual>
    <collision>
      <origin rpy="0 0 0" xyz="0 0 0"/>
      <geometry>
        <mesh filename="package://body_description/meshes/left_leg_link2.STL"/>
      </geometry>
    </collision>
  </link>
  <joint name="leg1_left_leg_joint2" type="revolute">
    <origin rpy="0 0 1.5481" xyz="0.061 0 0"/>
    <parent link="leg1_left_leg_link1"/>
    <child link="leg1_left_leg_link2"/>
    <axis xyz="0 0 1"/>
    <limit effort="100" lower="-3.14" upper="3.14" velocity="10"/>
    <mimic joint="leg1_left_leg_joint3" multiplier="-1"/>
  </joint>
  <link name="leg1_left_leg_link3">
    <inertial>
      <origin rpy="0 0 0" xyz="0.0004307 -0.015395 -0.01826"/>
      <mass value="0.0042639"/>
      <inertia ixx="1.5353E-06" ixy="8.5323E-09" ixz="8.9451E-10" iyy="1.3235E-06" iyz="-7.4296E-08" izz="3.5073E-07"/>
    </inertial>
    <visual>
      <origin rpy="0 0 0" xyz="0 0 0"/>
      <geometry>
        <mesh filename="package://body_description/meshes/left_leg_link3.STL"/>
      </geometry>
      <material name="">
        <color rgba="0.79216 0.81961 0.93333 1"/>
      </material>
    </visual>
    <collision>
      <origin rpy="0 0 0" xyz="0 0 0"/>
      <geometry>
        <mesh filename="package://body_description/meshes/left_leg_link3.STL"/>
      </geometry>
    </collision>
  </link>
  <joint name="leg1_left_leg_joint3" type="revolute">
    <origin rpy="0 0 -0.21172" xyz="0.0255 0 0"/>
    <parent link="leg1_left_leg_link1"/>
    <child link="leg1_left_leg_link3"/>
    <axis xyz="0 0 -1"/>
    <limit effort="100" lower="-3.14" upper="3.14" velocity="10"/>
  </joint>
  <link name="leg1_left_leg_link4">
    <inertial>
      <origin rpy="0 0 0" xyz="0.016434 1.8077E-12 -0.019911"/>
      <mass value="0.00053747"/>
      <inertia ixx="1.8438E-09" ixy="4.6176E-20" ixz="-8.7449E-13" iyy="4.7249E-09" iyz="-1.8552E-20" izz="5.3635E-09"/>
    </inertial>
    <visual>
      <origin rpy="0 0 0" xyz="0 0 0"/>
      <geometry>
        <mesh filename="package://body_description/meshes/left_leg_link4.STL"/>
      </geometry>
      <material name="">
        <color rgba="0.79216 0.81961 0.93333 1"/>
      </material>
    </visual>
    <collision>
      <origin rpy="0 0 0" xyz="0 0 0"/>
      <geometry>
        <mesh filename="package://body_description/meshes/left_leg_link4.STL"/>
      </geometry>
    </collision>
  </link>
  <joint name="leg1_left_leg_joint4" type="revolute">
    <origin rpy="0 0.0092257 0.50332" xyz="0.0084934 -0.020001 0"/>
    <parent link="leg1_left_leg_link3"/>
    <child link="leg1_left_leg_link4"/>
    <axis xyz="0 0 -1"/>
    <limit effort="100" lower="-3.14" upper="3.14" velocity="10"/>
    <mimic joint="leg1_left_leg_joint3" multiplier="-1"/>
  </joint>
  <joint name="leg1_joint" type="revolute">
    <origin rpy="0 0 -0.423478" xyz="0.057411 -0.004797 0"/>
    <parent link="base_link"/>
    <child link="leg1_left_leg_base_link"/>
    <axis xyz="0 0 1"/>
    <limit effort="100" lower="-3.14" upper="3.14" velocity="10"/>
  </joint>
  <link name="leg2_left_leg_base_link">
    <inertial>
      <origin rpy="0 0 0" xyz="0.022492 0.007129 -0.014892"/>
      <mass value="0.011294"/>
      <inertia ixx="1.7081E-06" ixy="8.3146E-08" ixz="-1.7531E-07" iyy="1.7861E-06" iyz="-1.213E-08" izz="1.1716E-06"/>
    </inertial>
    <visual>
      <origin rpy="0 0 0" xyz="0 0 0"/>
      <geometry>
        <mesh filename="package://body_description/meshes/left_leg_base_link.STL"/>
      </geometry>
      <material name="">
        <color rgba="0.79216 0.81961 0.93333 1"/>
      </material>
    </visual>
    <collision>
      <origin rpy="0 0 0" xyz="0 0 0"/>
      <geometry>
        <mesh filename="package://body_description/meshes/left_leg_base_link.STL"/>
      </geometry>
    </collision>
  </link>
  <link name="leg2_left_leg_link1">
    <inertial>
      <origin rpy="0 0 0" xyz="0.025933 0.0030528 -0.022581"/>
      <mass value="0.017021"/>
      <inertia ixx="2.0908E-06" ixy="1.3565E-08" ixz="-2.3118E-07" iyy="3.6034E-06" iyz="1.3164E-07" izz="2.9314E-06"/>
    </inertial>
    <visual>
      <origin rpy="0 0 0" xyz="0 0 0"/>
      <geometry>
        <mesh filename="package://body_description/meshes/left_leg_link1.STL"/>
      </geometry>
      <material name="">
        <color rgba="0.79216 0.81961 0.93333 1"/>
      </material>
    </visual>
    <collision>
      <origin rpy="0 0 0" xyz="0 0 0"/>
      <geometry>
        <mesh filename="package://body_description/meshes/left_leg_link1.STL"/>
      </geometry>
    </collision>
  </link>
  <joint name="leg2_left_leg_joint1" type="revolute">
    <origin rpy="-1.5708 -0.3068 0.34327" xyz="0.02198 0.027937 -0.00929"/>
    <parent link="leg2_left_leg_base_link"/>
    <child link="leg2_left_leg_link1"/>
    <axis xyz="0 0 1"/>
    <limit effort="100" lower="-3.14" upper="3.14" velocity="10"/>
  </joint>
  <link name="leg2_left_leg_link2">
    <inertial>
      <origin rpy="0 0 0" xyz="0.089594 -7.9936E-15 -0.018644"/>
      <mass value="0.014281"/>
      <inertia ixx="3.6992E-07" ixy="5.4925E-22" ixz="8.5365E-22" iyy="5.5689E-06" iyz="8.4703E-22" izz="5.6129E-06"/>
    </inertial>
    <visual>
      <origin rpy="0 0 0" xyz="0 0 0"/>
      <geometry>
        <mesh filename="package://body_description/meshes/left_leg_link2.STL"/>
      </geometry>
      <material name="">
        <color rgba="0.79216 0.81961 0.93333 1"/>
      </material>
    </visual>
    <collision>
      <origin rpy="0 0 0" xyz="0 0 0"/>
      <geometry>
        <mesh filename="package://body_description/meshes/left_leg_link2.STL"/>
      </geometry>
    </collision>
  </link>
  <joint name="leg2_left_leg_joint2" type="revolute">
    <origin rpy="0 0 1.5481" xyz="0.061 0 0"/>
    <parent link="leg2_left_leg_link1"/>
    <child link="leg2_left_leg_link2"/>
    <axis xyz="0 0 1"/>
    <limit effort="100" lower="-3.14" upper="3.14" velocity="10"/>
    <mimic joint="leg2_left_leg_joint3" multiplier="-1"/>
  </joint>
  <link name="leg2_left_leg_link3">
    <inertial>
      <origin rpy="0 0 0" xyz="0.0004307 -0.015395 -0.01826"/>
      <mass value="0.0042639"/>
      <inertia ixx="1.5353E-06" ixy="8.5323E-09" ixz="8.9451E-10" iyy="1.3235E-06" iyz="-7.4296E-08" izz="3.5073E-07"/>
    </inertial>
    <visual>
      <origin rpy="0 0 0" xyz="0 0 0"/>
      <geometry>
        <mesh filename="package://body_description/meshes/left_leg_link3.STL"/>
      </geometry>
      <material name="">
        <color rgba="0.79216 0.81961 0.93333 1"/>
      </material>
    </visual>
    <collision>
      <origin rpy="0 0 0" xyz="0 0 0"/>
      <geometry>
        <mesh filename="package://body_description/meshes/left_leg_link3.STL"/>
      </geometry>
    </collision>
  </link>
  <joint name="leg2_left_leg_joint3" type="revolute">
    <origin rpy="0 0 -0.21172" xyz="0.0255 0 0"/>
    <parent link="leg2_left_leg_link1"/>
    <child link="leg2_left_leg_link3"/>
    <axis xyz="0 0 -1"/>
    <limit effort="100" lower="-3.14" upper="3.14" velocity="10"/>
  </joint>
  <link name="leg2_left_leg_link4">
    <inertial>
      <origin rpy="0 0 0" xyz="0.016434 1.8077E-12 -0.019911"/>
      <mass value="0.00053747"/>
      <inertia ixx="1.8438E-09" ixy="4.6176E-20" ixz="-8.7449E-13" iyy="4.7249E-09" iyz="-1.8552E-20" izz="5.3635E-09"/>
    </inertial>
    <visual>
      <origin rpy="0 0 0" xyz="0 0 0"/>
      <geometry>
        <mesh filename="package://body_description/meshes/left_leg_link4.STL"/>
      </geometry>
      <material name="">
        <color rgba="0.79216 0.81961 0.93333 1"/>
      </material>
    </visual>
    <collision>
      <origin rpy="0 0 0" xyz="0 0 0"/>
      <geometry>
        <mesh filename="package://body_description/meshes/left_leg_link4.STL"/>
      </geometry>
    </collision>
  </link>
  <joint name="leg2_left_leg_joint4" type="revolute">
    <origin rpy="0 0.0092257 0.50332" xyz="0.0084934 -0.020001 0"/>
    <parent link="leg2_left_leg_link3"/>
    <child link="leg2_left_leg_link4"/>
    <axis xyz="0 0 -1"/>
    <limit effort="100" lower="-3.14" upper="3.14" velocity="10"/>
    <mimic joint="leg2_left_leg_joint3" multiplier="-1"/>
  </joint>
  <joint name="leg2_joint" type="revolute">
    <origin rpy="0 0 0.62372" xyz="0.03286 0.047321 0"/>
    <parent link="base_link"/>
    <child link="leg2_left_leg_base_link"/>
    <axis xyz="0 0 1"/>
    <limit effort="100" lower="-3.14" upper="3.14" velocity="10"/>
  </joint>
  <link name="leg3_left_leg_base_link">
    <inertial>
      <origin rpy="0 0 0" xyz="0.022492 0.007129 -0.014892"/>
      <mass value="0.011294"/>
      <inertia ixx="1.7081E-06" ixy="8.3146E-08" ixz="-1.7531E-07" iyy="1.7861E-06" iyz="-1.213E-08" izz="1.1716E-06"/>
    </inertial>
    <visual>
      <origin rpy="0 0 0" xyz="0 0 0"/>
      <geometry>
        <mesh filename="package://body_description/meshes/left_leg_base_link.STL"/>
      </geometry>
      <material name="">
        <color rgba="0.79216 0.81961 0.93333 1"/>
      </material>
    </visual>
    <collision>
      <origin rpy="0 0 0" xyz="0 0 0"/>
      <geometry>
        <mesh filename="package://body_description/meshes/left_leg_base_link.STL"/>
      </geometry>
    </collision>
  </link>
  <link name="leg3_left_leg_link1">
    <inertial>
      <origin rpy="0 0 0" xyz="0.025933 0.0030528 -0.022581"/>
      <mass value="0.017021"/>
      <inertia ixx="2.0908E-06" ixy="1.3565E-08" ixz="-2.3118E-07" iyy="3.6034E-06" iyz="1.3164E-07" izz="2.9314E-06"/>
    </inertial>
    <visual>
      <origin rpy="0 0 0" xyz="0 0 0"/>
      <geometry>
        <mesh filename="package://body_description/meshes/left_leg_link1.STL"/>
      </geometry>
      <material name="">
        <color rgba="0.79216 0.81961 0.93333 1"/>
      </material>
    </visual>
    <collision>
      <origin rpy="0 0 0" xyz="0 0 0"/>
      <geometry>
        <mesh filename="package://body_description/meshes/left_leg_link1.STL"/>
      </geometry>
    </collision>
  </link>
  <joint name="leg3_left_leg_joint1" type="revolute">
    <origin rpy="-1.5708 -0.3068 0.34327" xyz="0.02198 0.027937 -0.00929"/>
    <parent link="leg3_left_leg_base_link"/>
    <child link="leg3_left_leg_link1"/>
    <axis xyz="0 0 1"/>
    <limit effort="100" lower="-3.14" upper="3.14" velocity="10"/>
  </joint>
  <link name="leg3_left_leg_link2">
    <inertial>
      <origin rpy="0 0 0" xyz="0.089594 -7.9936E-15 -0.018644"/>
      <mass value="0.014281"/>
      <inertia ixx="3.6992E-07" ixy="5.4925E-22" ixz="8.5365E-22" iyy="5.5689E-06" iyz="8.4703E-22" izz="5.6129E-06"/>
    </inertial>
    <visual>
      <origin rpy="0 0 0" xyz="0 0 0"/>
      <geometry>
        <mesh filename="package://body_description/meshes/left_leg_link2.STL"/>
      </geometry>
      <material name="">
        <color rgba="0.79216 0.81961 0.93333 1"/>
      </material>
    </visual>
    <collision>
      <origin rpy="0 0 0" xyz="0 0 0"/>
      <geometry>
        <mesh filename="package://body_description/meshes/left_leg_link2.STL"/>
      </geometry>
    </collision>
  </link>
  <joint name="leg3_left_leg_joint2" type="revolute">
    <origin rpy="0 0 1.5481" xyz="0.061 0 0"/>
    <parent link="leg3_left_leg_link1"/>
    <child link="leg3_left_leg_link2"/>
    <axis xyz="0 0 1"/>
    <limit effort="100" lower="-3.14" upper="3.14" velocity="10"/>
    <mimic joint="leg3_left_leg_joint3" multiplier="-1"/>
  </joint>
  <link name="leg3_left_leg_link3">
    <inertial>
      <origin rpy="0 0 0" xyz="0.0004307 -0.015395 -0.01826"/>
      <mass value="0.0042639"/>
      <inertia ixx="1.5353E-06" ixy="8.5323E-09" ixz="8.9451E-10" iyy="1.3235E-06" iyz="-7.4296E-08" izz="3.5073E-07"/>
    </inertial>
    <visual>
      <origin rpy="0 0 0" xyz="0 0 0"/>
      <geometry>
        <mesh filename="package://body_description/meshes/left_leg_link3.STL"/>
      </geometry>
      <material name="">
        <color rgba="0.79216 0.81961 0.93333 1"/>
      </material>
    </visual>
    <collision>
      <origin rpy="0 0 0" xyz="0 0 0"/>
      <geometry>
        <mesh filename="package://body_description/meshes/left_leg_link3.STL"/>
      </geometry>
    </collision>
  </link>
  <joint name="leg3_left_leg_joint3" type="revolute">
    <origin rpy="0 0 -0.21172" xyz="0.0255 0 0"/>
    <parent link="leg3_left_leg_link1"/>
    <child link="leg3_left_leg_link3"/>
    <axis xyz="0 0 -1"/>
    <limit effort="100" lower="-3.14" upper="3.14" velocity="10"/>
  </joint>
  <link name="leg3_left_leg_link4">
    <inertial>
      <origin rpy="0 0 0" xyz="0.016434 1.8077E-12 -0.019911"/>
      <mass value="0.00053747"/>
      <inertia ixx="1.8438E-09" ixy="4.6176E-20" ixz="-8.7449E-13" iyy="4.7249E-09" iyz="-1.8552E-20" izz="5.3635E-09"/>
    </inertial>
    <visual>
      <origin rpy="0 0 0" xyz="0 0 0"/>
      <geometry>
        <mesh filename="package://body_description/meshes/left_leg_link4.STL"/>
      </geometry>
      <material name="">
        <color rgba="0.79216 0.81961 0.93333 1"/>
      </material>
    </visual>
    <collision>
      <origin rpy="0 0 0" xyz="0 0 0"/>
      <geometry>
        <mesh filename="package://body_description/meshes/left_leg_link4.STL"/>
      </geometry>
    </collision>
  </link>
  <joint name="leg3_left_leg_joint4" type="revolute">
    <origin rpy="0 0.0092257 0.50332" xyz="0.0084934 -0.020001 0"/>
    <parent link="leg3_left_leg_link3"/>
    <child link="leg3_left_leg_link4"/>
    <axis xyz="0 0 -1"/>
    <limit effort="100" lower="-3.14" upper="3.14" velocity="10"/>
    <mimic joint="leg3_left_leg_joint3" multiplier="-1"/>
  </joint>
  <joint name="leg3_joint" type="revolute">
    <origin rpy="0 0 1.6709" xyz="-0.024551 0.052118 0"/>
    <parent link="base_link"/>
    <child link="leg3_left_leg_base_link"/>
    <axis xyz="0 0 1"/>
    <limit effort="100" lower="-3.14" upper="3.14" velocity="10"/>
  </joint>
  <link name="leg4_right_leg_base_link">
    <inertial>
      <origin rpy="0 0 0" xyz="0.021397 0.0099443 -0.014892"/>
      <mass value="0.011294"/>
      <inertia ixx="1.8266E-06" ixy="-4.6095E-08" ixz="-1.3742E-07" iyy="1.6677E-06" iyz="-1.0952E-07" izz="1.1716E-06"/>
    </inertial>
    <visual>
      <origin rpy="0 0 0" xyz="0 0 0"/>
      <geometry>
        <mesh filename="package://body_description/meshes/right_leg_base_link.STL"/>
      </geometry>
      <material name="">
        <color rgba="0.79216 0.81961 0.93333 1"/>
      </material>
    </visual>
    <collision>
      <origin rpy="0 0 0" xyz="0 0 0"/>
      <geometry>
        <mesh filename="package://body_description/meshes/right_leg_base_link.STL"/>
      </geometry>
    </collision>
  </link>
  <link name="leg4_right_leg_link1">
    <inertial>
      <origin rpy="0 0 0" xyz="0.025933 -0.0030528 -0.022581"/>
      <mass value="0.017021"/>
      <inertia ixx="2.0908E-06" ixy="-1.3565E-08" ixz="-2.3118E-07" iyy="3.6034E-06" iyz="-1.3164E-07" izz="2.9314E-06"/>
    </inertial>
    <visual>
      <origin rpy="0 0 0" xyz="0 0 0"/>
      <geometry>
        <mesh filename="package://body_description/meshes/right_leg_link1.STL"/>
      </geometry>
      <material name="">
        <color rgba="0.79216 0.81961 0.93333 1"/>
      </material>
    </visual>
    <collision>
      <origin rpy="0 0 0" xyz="0 0 0"/>
      <geometry>
        <mesh filename="package://body_description/meshes/right_leg_link1.STL"/>
      </geometry>
    </collision>
  </link>
  <joint name="leg4_right_leg_joint1" type="revolute">
    <origin rpy="1.5708 -0.51606 0.39873" xyz="0.035081 -0.0057403 -0.00929"/>
    <parent link="leg4_right_leg_base_link"/>
    <child link="leg4_right_leg_link1"/>
    <axis xyz="0 0 1"/>
    <limit effort="100" lower="-3.14" upper="3.14" velocity="10"/>
  </joint>
  <link name="leg4_right_leg_link2">
    <inertial>
      <origin rpy="0 0 0" xyz="0.089594 -6.8001E-15 -0.018644"/>
      <mass value="0.014281"/>
      <inertia ixx="3.6992E-07" ixy="1.0965E-19" ixz="2.2466E-21" iyy="5.5689E-06" iyz="0" izz="5.6129E-06"/>
    </inertial>
    <visual>
      <origin rpy="0 0 0" xyz="0 0 0"/>
      <geometry>
        <mesh filename="package://body_description/meshes/right_leg_link2.STL"/>
      </geometry>
      <material name="">
        <color rgba="0.79216 0.81961 0.93333 1"/>
      </material>
    </visual>
    <collision>
      <origin rpy="0 0 0" xyz="0 0 0"/>
      <geometry>
        <mesh filename="package://body_description/meshes/right_leg_link2.STL"/>
      </geometry>
    </collision>
  </link>
  <joint name="leg4_right_leg_joint2" type="revolute">
    <origin rpy="0 0 -1.7773" xyz="0.061 0 0"/>
    <parent link="leg4_right_leg_link1"/>
    <child link="leg4_right_leg_link2"/>
    <axis xyz="0 0 1"/>
    <limit effort="100" lower="-3.14" upper="3.14" velocity="10"/>
    <mimic joint="leg4_right_leg_joint3" multiplier="-1"/>
  </joint>
  <link name="leg4_right_leg_link3">
    <inertial>
      <origin rpy="0 0 0" xyz="0.00040437 0.014672 -0.020116"/>
      <mass value="0.0046109"/>
      <inertia ixx="1.552E-06" ixy="-8.5323E-09" ixz="8.9451E-10" iyy="1.3255E-06" iyz="7.5364E-08" izz="3.6852E-07"/>
    </inertial>
    <visual>
      <origin rpy="0 0 0" xyz="0 0 0"/>
      <geometry>
        <mesh filename="package://body_description/meshes/right_leg_link3.STL"/>
      </geometry>
      <material name="">
        <color rgba="0.79216 0.81961 0.93333 1"/>
      </material>
    </visual>
    <collision>
      <origin rpy="0 0 0" xyz="0 0 0"/>
      <geometry>
        <mesh filename="package://body_description/meshes/right_leg_link3.STL"/>
      </geometry>
    </collision>
  </link>
  <joint name="leg4_right_leg_joint3" type="revolute">
    <origin rpy="0 0 0.088197" xyz="0.025507 0 0"/>
    <parent link="leg4_right_leg_link1"/>
    <child link="leg4_right_leg_link3"/>
    <axis xyz="0 0 -1"/>
    <limit effort="100" lower="-3.14" upper="3.14" velocity="10"/>
  </joint>
  <link name="leg4_right_leg_link4">
    <inertial>
      <origin rpy="0 0 0" xyz="0.015829 0.00093361 -0.0068248"/>
      <mass value="0.00053747"/>
      <inertia ixx="1.8438E-09" ixy="-4.6086E-19" ixz="8.7449E-13" iyy="4.7249E-09" iyz="-3.9428E-20" izz="5.3635E-09"/>
    </inertial>
    <visual>
      <origin rpy="0 0 0" xyz="0 0 0"/>
      <geometry>
        <mesh filename="package://body_description/meshes/right_leg_link4.STL"/>
      </geometry>
      <material name="">
        <color rgba="0.79216 0.81961 0.93333 1"/>
      </material>
    </visual>
    <collision>
      <origin rpy="0 0 0" xyz="0 0 0"/>
      <geometry>
        <mesh filename="package://body_description/meshes/right_leg_link4.STL"/>
      </geometry>
    </collision>
  </link>
  <joint name="leg4_right_leg_joint4" type="revolute">
    <origin rpy="0 -0.0092257 -0.36643" xyz="0.0085 0.019 -0.01074"/>
    <parent link="leg4_right_leg_link3"/>
    <child link="leg4_right_leg_link4"/>
    <axis xyz="-0.0092256 0 -0.99996"/>
    <limit effort="100" lower="-3.14" upper="3.14" velocity="10"/>
    <mimic joint="leg4_right_leg_joint3" multiplier="-1"/>
  </joint>
  <joint name="leg4_joint" type="revolute">
    <origin rpy="0 0 2.6781" xyz="-0.057411 0.004797 0"/>
    <parent link="base_link"/>
    <child link="leg4_right_leg_base_link"/>
    <axis xyz="0 0 1"/>
    <limit effort="100" lower="-3.14" upper="3.14" velocity="10"/>
  </joint>
  <link name="leg5_right_leg_base_link">
    <inertial>
      <origin rpy="0 0 0" xyz="0.021397 0.0099443 -0.014892"/>
      <mass value="0.011294"/>
      <inertia ixx="1.8266E-06" ixy="-4.6095E-08" ixz="-1.3742E-07" iyy="1.6677E-06" iyz="-1.0952E-07" izz="1.1716E-06"/>
    </inertial>
    <visual>
      <origin rpy="0 0 0" xyz="0 0 0"/>
      <geometry>
        <mesh filename="package://body_description/meshes/right_leg_base_link.STL"/>
      </geometry>
      <material name="">
        <color rgba="0.79216 0.81961 0.93333 1"/>
      </material>
    </visual>
    <collision>
      <origin rpy="0 0 0" xyz="0 0 0"/>
      <geometry>
        <mesh filename="package://body_description/meshes/right_leg_base_link.STL"/>
      </geometry>
    </collision>
  </link>
  <link name="leg5_right_leg_link1">
    <inertial>
      <origin rpy="0 0 0" xyz="0.025933 -0.0030528 -0.022581"/>
      <mass value="0.017021"/>
      <inertia ixx="2.0908E-06" ixy="-1.3565E-08" ixz="-2.3118E-07" iyy="3.6034E-06" iyz="-1.3164E-07" izz="2.9314E-06"/>
    </inertial>
    <visual>
      <origin rpy="0 0 0" xyz="0 0 0"/>
      <geometry>
        <mesh filename="package://body_description/meshes/right_leg_link1.STL"/>
      </geometry>
      <material name="">
        <color rgba="0.79216 0.81961 0.93333 1"/>
      </material>
    </visual>
    <collision>
      <origin rpy="0 0 0" xyz="0 0 0"/>
      <geometry>
        <mesh filename="package://body_description/meshes/right_leg_link1.STL"/>
      </geometry>
    </collision>
  </link>
  <joint name="leg5_right_leg_joint1" type="revolute">
    <origin rpy="1.5708 -0.51606 0.39873" xyz="0.035081 -0.0057403 -0.00929"/>
    <parent link="leg5_right_leg_base_link"/>
    <child link="leg5_right_leg_link1"/>
    <axis xyz="0 0 1"/>
    <limit effort="100" lower="-3.14" upper="3.14" velocity="10"/>
  </joint>
  <link name="leg5_right_leg_link2">
    <inertial>
      <origin rpy="0 0 0" xyz="0.089594 -6.8001E-15 -0.018644"/>
      <mass value="0.014281"/>
      <inertia ixx="3.6992E-07" ixy="1.0965E-19" ixz="2.2466E-21" iyy="5.5689E-06" iyz="0" izz="5.6129E-06"/>
    </inertial>
    <visual>
      <origin rpy="0 0 0" xyz="0 0 0"/>
      <geometry>
        <mesh filename="package://body_description/meshes/right_leg_link2.STL"/>
      </geometry>
      <material name="">
        <color rgba="0.79216 0.81961 0.93333 1"/>
      </material>
    </visual>
    <collision>
      <origin rpy="0 0 0" xyz="0 0 0"/>
      <geometry>
        <mesh filename="package://body_description/meshes/right_leg_link2.STL"/>
      </geometry>
    </collision>
  </link>
  <joint name="leg5_right_leg_joint2" type="revolute">
    <origin rpy="0 0 -1.7773" xyz="0.061 0 0"/>
    <parent link="leg5_right_leg_link1"/>
    <child link="leg5_right_leg_link2"/>
    <axis xyz="0 0 1"/>
    <limit effort="100" lower="-3.14" upper="3.14" velocity="10"/>
    <mimic joint="leg5_right_leg_joint3" multiplier="-1"/>
  </joint>
  <link name="leg5_right_leg_link3">
    <inertial>
      <origin rpy="0 0 0" xyz="0.00040437 0.014672 -0.020116"/>
      <mass value="0.0046109"/>
      <inertia ixx="1.552E-06" ixy="-8.5323E-09" ixz="8.9451E-10" iyy="1.3255E-06" iyz="7.5364E-08" izz="3.6852E-07"/>
    </inertial>
    <visual>
      <origin rpy="0 0 0" xyz="0 0 0"/>
      <geometry>
        <mesh filename="package://body_description/meshes/right_leg_link3.STL"/>
      </geometry>
      <material name="">
        <color rgba="0.79216 0.81961 0.93333 1"/>
      </material>
    </visual>
    <collision>
      <origin rpy="0 0 0" xyz="0 0 0"/>
      <geometry>
        <mesh filename="package://body_description/meshes/right_leg_link3.STL"/>
      </geometry>
    </collision>
  </link>
  <joint name="leg5_right_leg_joint3" type="revolute">
    <origin rpy="0 0 0.088197" xyz="0.025507 0 0"/>
    <parent link="leg5_right_leg_link1"/>
    <child link="leg5_right_leg_link3"/>
    <axis xyz="0 0 -1"/>
    <limit effort="100" lower="-3.14" upper="3.14" velocity="10"/>
  </joint>
  <link name="leg5_right_leg_link4">
    <inertial>
      <origin rpy="0 0 0" xyz="0.015829 0.00093361 -0.0068248"/>
      <mass value="0.00053747"/>
      <inertia ixx="1.8438E-09" ixy="-4.6086E-19" ixz="8.7449E-13" iyy="4.7249E-09" iyz="-3.9428E-20" izz="5.3635E-09"/>
    </inertial>
    <visual>
      <origin rpy="0 0 0" xyz="0 0 0"/>
      <geometry>
        <mesh filename="package://body_description/meshes/right_leg_link4.STL"/>
      </geometry>
      <material name="">
        <color rgba="0.79216 0.81961 0.93333 1"/>
      </material>
    </visual>
    <collision>
      <origin rpy="0 0 0" xyz="0 0 0"/>
      <geometry>
        <mesh filename="package://body_description/meshes/right_leg_link4.STL"/>
      </geometry>
    </collision>
  </link>
  <joint name="leg5_right_leg_joint4" type="revolute">
    <origin rpy="0 -0.0092257 -0.36643" xyz="0.0085 0.019 -0.01074"/>
    <parent link="leg5_right_leg_link3"/>
    <child link="leg5_right_leg_link4"/>
    <axis xyz="-0.0092256 0 -0.99996"/>
    <limit effort="100" lower="-3.14" upper="3.14" velocity="10"/>
    <mimic joint="leg5_right_leg_joint3" multiplier="-1"/>
  </joint>
  <joint name="leg5_joint" type="revolute">
    <origin rpy="0 0 -2.5579" xyz="-0.03286 -0.047321 0"/>
    <parent link="base_link"/>
    <child link="leg5_right_leg_base_link"/>
    <axis xyz="0 0 1"/>
    <limit effort="100" lower="-3.14" upper="3.14" velocity="10"/>
  </joint>
  <link name="leg6_right_leg_base_link">
    <inertial>
      <origin rpy="0 0 0" xyz="0.021397 0.0099443 -0.014892"/>
      <mass value="0.011294"/>
      <inertia ixx="1.8266E-06" ixy="-4.6095E-08" ixz="-1.3742E-07" iyy="1.6677E-06" iyz="-1.0952E-07" izz="1.1716E-06"/>
    </inertial>
    <visual>
      <origin rpy="0 0 0" xyz="0 0 0"/>
      <geometry>
        <mesh filename="package://body_description/meshes/right_leg_base_link.STL"/>
      </geometry>
      <material name="">
        <color rgba="0.79216 0.81961 0.93333 1"/>
      </material>
    </visual>
    <collision>
      <origin rpy="0 0 0" xyz="0 0 0"/>
      <geometry>
        <mesh filename="package://body_description/meshes/right_leg_base_link.STL"/>
      </geometry>
    </collision>
  </link>
  <link name="leg6_right_leg_link1">
    <inertial>
      <origin rpy="0 0 0" xyz="0.025933 -0.0030528 -0.022581"/>
      <mass value="0.017021"/>
      <inertia ixx="2.0908E-06" ixy="-1.3565E-08" ixz="-2.3118E-07" iyy="3.6034E-06" iyz="-1.3164E-07" izz="2.9314E-06"/>
    </inertial>
    <visual>
      <origin rpy="0 0 0" xyz="0 0 0"/>
      <geometry>
        <mesh filename="package://body_description/meshes/right_leg_link1.STL"/>
      </geometry>
      <material name="">
        <color rgba="0.79216 0.81961 0.93333 1"/>
      </material>
    </visual>
    <collision>
      <origin rpy="0 0 0" xyz="0 0 0"/>
      <geometry>
        <mesh filename="package://body_description/meshes/right_leg_link1.STL"/>
      </geometry>
    </collision>
  </link>
  <joint name="leg6_right_leg_joint1" type="revolute">
    <origin rpy="1.5708 -0.51606 0.39873" xyz="0.035081 -0.0057403 -0.00929"/>
    <parent link="leg6_right_leg_base_link"/>
    <child link="leg6_right_leg_link1"/>
    <axis xyz="0 0 1"/>
    <limit effort="100" lower="-3.14" upper="3.14" velocity="10"/>
  </joint>
  <link name="leg6_right_leg_link2">
    <inertial>
      <origin rpy="0 0 0" xyz="0.089594 -6.8001E-15 -0.018644"/>
      <mass value="0.014281"/>
      <inertia ixx="3.6992E-07" ixy="1.0965E-19" ixz="2.2466E-21" iyy="5.5689E-06" iyz="0" izz="5.6129E-06"/>
    </inertial>
    <visual>
      <origin rpy="0 0 0" xyz="0 0 0"/>
      <geometry>
        <mesh filename="package://body_description/meshes/right_leg_link2.STL"/>
      </geometry>
      <material name="">
        <color rgba="0.79216 0.81961 0.93333 1"/>
      </material>
    </visual>
    <collision>
      <origin rpy="0 0 0" xyz="0 0 0"/>
      <geometry>
        <mesh filename="package://body_description/meshes/right_leg_link2.STL"/>
      </geometry>
    </collision>
  </link>
  <joint name="leg6_right_leg_joint2" type="revolute">
    <origin rpy="0 0 -1.7773" xyz="0.061 0 0"/>
    <parent link="leg6_right_leg_link1"/>
    <child link="leg6_right_leg_link2"/>
    <axis xyz="0 0 1"/>
    <limit effort="100" lower="-3.14" upper="3.14" velocity="10"/>
    <mimic joint="leg6_right_leg_joint3" multiplier="-1"/>
  </joint>
  <link name="leg6_right_leg_link3">
    <inertial>
      <origin rpy="0 0 0" xyz="0.00040437 0.014672 -0.020116"/>
      <mass value="0.0046109"/>
      <inertia ixx="1.552E-06" ixy="-8.5323E-09" ixz="8.9451E-10" iyy="1.3255E-06" iyz="7.5364E-08" izz="3.6852E-07"/>
    </inertial>
    <visual>
      <origin rpy="0 0 0" xyz="0 0 0"/>
      <geometry>
        <mesh filename="package://body_description/meshes/right_leg_link3.STL"/>
      </geometry>
      <material name="">
        <color rgba="0.79216 0.81961 0.93333 1"/>
      </material>
    </visual>
    <collision>
      <origin rpy="0 0 0" xyz="0 0 0"/>
      <geometry>
        <mesh filename="package://body_description/meshes/right_leg_link3.STL"/>
      </geometry>
    </collision>
  </link>
  <joint name="leg6_right_leg_joint3" type="revolute">
    <origin rpy="0 0 0.088197" xyz="0.025507 0 0"/>
    <parent link="leg6_right_leg_link1"/>
    <child link="leg6_right_leg_link3"/>
    <axis xyz="0 0 -1"/>
    <limit effort="100" lower="-3.14" upper="3.14" velocity="10"/>
  </joint>
  <link name="leg6_right_leg_link4">
    <inertial>
      <origin rpy="0 0 0" xyz="0.015829 0.00093361 -0.0068248"/>
      <mass value="0.00053747"/>
      <inertia ixx="1.8438E-09" ixy="-4.6086E-19" ixz="8.7449E-13" iyy="4.7249E-09" iyz="-3.9428E-20" izz="5.3635E-09"/>
    </inertial>
    <visual>
      <origin rpy="0 0 0" xyz="0 0 0"/>
      <geometry>
        <mesh filename="package://body_description/meshes/right_leg_link4.STL"/>
      </geometry>
      <material name="">
        <color rgba="0.79216 0.81961 0.93333 1"/>
      </material>
    </visual>
    <collision>
      <origin rpy="0 0 0" xyz="0 0 0"/>
      <geometry>
        <mesh filename="package://body_description/meshes/right_leg_link4.STL"/>
      </geometry>
    </collision>
  </link>
  <joint name="leg6_right_leg_joint4" type="revolute">
    <origin rpy="0 -0.0092257 -0.36643" xyz="0.0085 0.019 -0.01074"/>
    <parent link="leg6_right_leg_link3"/>
    <child link="leg6_right_leg_link4"/>
    <axis xyz="-0.0092256 0 -0.99996"/>
    <limit effort="100" lower="-3.14" upper="3.14" velocity="10"/>
    <mimic joint="leg6_right_leg_joint3" multiplier="-1"/>
  </joint>
  <joint name="leg6_joint" type="revolute">
    <origin rpy="0 0 -1.5107" xyz="0.024551 -0.052118 0"/>
    <parent link="base_link"/>
    <child link="leg6_right_leg_base_link"/>
    <axis xyz="0 0 1"/>
    <limit effort="100" lower="-3.14" upper="3.14" velocity="10"/>
  </joint>
</robot>
