#VRML_SIM R2025a utf8
# license: Apache License 2.0
# license url: http://www.apache.org/licenses/LICENSE-2.0

PROTO BodyDescription [
  field  SFVec3f     translation     0 0 0
  field  SFRotation  rotation        0 0 1 0
  field  SFString    name            "BodyDescription"
  field  SFString    controller      "void"
  # 预先列出所有关节名，方便 Scene Tree 一次性创建 controllerArgs
  field  MFString    controllerArgs  [
    "leg1_joint"
    "leg1_left_leg_joint1" "leg1_left_leg_joint2" "leg1_left_leg_joint3" "leg1_left_leg_joint4"
    "leg2_joint"
    "leg2_left_leg_joint1" "leg2_left_leg_joint2" "leg2_left_leg_joint3" "leg2_left_leg_joint4"
    "leg3_joint"
    "leg3_left_leg_joint1" "leg3_left_leg_joint2" "leg3_left_leg_joint3" "leg3_left_leg_joint4"
    "leg4_joint"
    "leg4_right_leg_joint1" "leg4_right_leg_joint2" "leg4_right_leg_joint3" "leg4_right_leg_joint4"
    "leg5_joint"
    "leg5_right_leg_joint1" "leg5_right_leg_joint2" "leg5_right_leg_joint3" "leg5_right_leg_joint4"
    "leg6_joint"
    "leg6_right_leg_joint1" "leg6_right_leg_joint2" "leg6_right_leg_joint3" "leg6_right_leg_joint4"
  ]
  field  SFString    customData      ""
  field  SFBool      supervisor      FALSE
  field  SFBool      synchronization TRUE
  field  SFBool      selfCollision   FALSE
]
{
  Robot {
    translation IS translation
    rotation      IS rotation
    controller    IS controller
    controllerArgs IS controllerArgs
    customData    IS customData
    supervisor    IS supervisor
    synchronization IS synchronization
    selfCollision IS selfCollision
    children [
      # -- Base Link Mesh --
      Shape {
        appearance DEF base_link_material PBRAppearance {
          baseColor 0.79216 0.81961 0.93333
          roughness 1
          metalness 0
        }
        geometry DEF base_link Mesh {
          url "C:/Users/bj/iCloudDrive/Desktop/windows file/research/spider/body_description/meshes/base_link.STL"
        }
      }

      # -- LEG 1 main joint --
      HingeJoint {
        jointParameters HingeJointParameters {
          axis   0 0 1
          anchor 0.057411 -0.004797 0
        }
        device [
          RotationalMotor {
            name        "leg1_joint"
            maxVelocity 10
            minPosition -3.14
            maxPosition 3.14
            maxTorque   100
          }
          PositionSensor { name "leg1_joint_sensor" }
        ]
        endPoint Solid {
          translation 0.057411 -0.004797 0
          rotation    0 0 -1 0.423478
          children [
            # -- LEG1 link 0 --
            Shape {
              appearance PBRAppearance { baseColor 0.79216 0.81961 0.93333 roughness 1 metalness 0 }
              geometry DEF left_leg_base_link Mesh {
                url "C:/Users/bj/iCloudDrive/Desktop/windows file/research/spider/body_description/meshes/left_leg_base_link.STL"
              }
            }
            # -- LEG1 sub-joint 1 --
            HingeJoint {
              jointParameters HingeJointParameters {
                axis   -0.336567 0.941659 -0.000004
                anchor 0.021980  0.027937 -0.009290
              }
              device [
                RotationalMotor {
                  name        "leg1_left_leg_joint1"
                  maxVelocity 10
                  minPosition -3.14
                  maxPosition 3.14
                  maxTorque   100
                }
                PositionSensor { name "leg1_left_leg_joint1_sensor" }
              ]
              endPoint Solid {
                translation 0.02198 0.027937 -0.00929
                rotation   -0.947482 -0.319288 0.01823 1.571132
                children [
                  # -- LEG1 link1 --
                  Shape {
                    appearance PBRAppearance { baseColor 0.79216 0.81961 0.93333 roughness 1 metalness 0 }
                    geometry DEF left_leg_link1 Mesh {
                      url "C:/Users/bj/iCloudDrive/Desktop/windows file/research/spider/body_description/meshes/left_leg_link1.STL"
                    }
                  }
                  # -- sub-joint 2 --
                  HingeJoint {
                    jointParameters HingeJointParameters {
                      axis   0 0 1
                      anchor 0.061 0 0
                    }
                    device [
                      RotationalMotor {
                        name        "leg1_left_leg_joint2"
                        maxVelocity 10
                        minPosition -3.14
                        maxPosition 3.14
                        maxTorque   100
                      }
                      PositionSensor { name "leg1_left_leg_joint2_sensor" }
                    ]
                    endPoint Solid {
                      translation 0.061 0 0
                      rotation    0 0 1 1.5481
                      children [
                        # -- LEG1 link2 --
                        Shape {
                          appearance PBRAppearance { baseColor 0.79216 0.81961 0.93333 roughness 1 metalness 0 }
                          geometry DEF left_leg_link2 Mesh {
                            url "C:/Users/bj/iCloudDrive/Desktop/windows file/research/spider/body_description/meshes/left_leg_link2.STL"
                          }
                        }
                      ]
                    }
                  }
                  # -- sub-joint 3 --
                  HingeJoint {
                    jointParameters HingeJointParameters {
                      axis   0 0 -1
                      anchor 0.0255 0 0
                    }
                    device [
                      RotationalMotor {
                        name        "leg1_left_leg_joint3"
                        maxVelocity 10
                        minPosition -3.14
                        maxPosition 3.14
                        maxTorque   100
                      }
                      PositionSensor { name "leg1_left_leg_joint3_sensor" }
                    ]
                    endPoint Solid {
                      translation 0.0255 0 0
                      rotation    0 0 -1 0.21172
                      children [
                        # -- sub-joint 4 --
                        HingeJoint {
                          jointParameters HingeJointParameters {
                            axis   -0.008081 -0.00445 -0.999957
                            anchor 0.008493 -0.020001 0
                          }
                          device [
                            RotationalMotor {
                              name        "leg1_left_leg_joint4"
                              maxVelocity 10
                              minPosition -3.14
                              maxPosition 3.14
                              maxTorque   100
                            }
                            PositionSensor { name "leg1_left_leg_joint4_sensor" }
                          ]
                          endPoint Solid {
                            translation 0.008493 -0.020001 0
                            rotation    -0.004612 0.017938 0.999828 0.503403
                            children [
                              # -- LEG1 link4 --
                              Shape {
                                appearance PBRAppearance { baseColor 0.79216 0.81961 0.93333 roughness 1 metalness 0 }
                                geometry DEF left_leg_link4 Mesh {
                                  url "C:/Users/bj/iCloudDrive/Desktop/windows file/research/spider/body_description/meshes/left_leg_link4.STL"
                                }
                              }
                            ]
                          }
                        }
                      ]
                    }
                  }
                ]
              }
            }
          ]
        }
      }

      # -- 后面 leg2 到 leg6 的定义同上（仅改 joint 名字、anchor、axis、mesh url） --
      # 你可以直接复制上面 leg1 的块，然后把
      #    "leg1_..." 全部替换成 "leg2_..."、"leg3_…" … "leg6_…"
      #    mesh 的 url 改成相应的 right_leg_*.STL 或 leg*.STL
      #   并把字段 device 中的 name, sensor 名称按 leg2, leg3 ... leg6 逐一替换。

    ]  # end children

    name IS name
    boundingObject USE base_link
    # physics 可保留或删掉，如果不需要模拟力学可以省略
    physics Physics {
      density      -1
      mass         0.093105
      centerOfMass [ -0.000055 0.000099 -0.018675 ]
      inertiaMatrix [
        4.1311e-05 4.248e-05 8.2447e-05
        1.2608e-06 4.332e-08 -7.8832e-08
      ]
    }
  }
}
